Workbook

Sheet Read Me
A1: BizTrackBD: manual QC / QA checklist
A2: Covers the marketing site, the customer store, the store admin and the platform (super) admin, end to end.
A4: How to use
A5: 1 | B5: Do the Setup sheet first. Nothing else is meaningful until the environment, migrations, accounts and test data are right.
A6: 2 | B6: Go sheet by sheet (numbers 2 to 20). In each row, follow Steps and compare with Expected result.
A7: 3 | B7: Mark 'Phone 390px' and 'Desktop 1440px' with Pass, Fail, Blocked or N/A (drop-down). The Result column fills itself.
A8: 4 | B8: On any Fail: write the bug id in 'Bug ref / notes' and add a row on the Defect log sheet (screenshot, steps, actual result).
A9: 5 | B9: Retest after each fix, then mark the check again. Keep the Tester and Date columns filled for the audit trail.
A10: 6 | B10: The Summary sheet counts everything and gives a release recommendation. After every release run the 'Smoke (30 min)' sheet.
A12: Result words
A13: Pass | B13: Works exactly as Expected on that device.
A14: Fail | B14: Does not match Expected, or errors. Always log a defect.
A15: Blocked | B15: Cannot test (missing data, environment down, earlier bug). Say why in notes.
A16: N/A | B16: Does not apply on that device or for this store setup.
A17: In progress | B17: One device done, the other not yet.
A18: Not run | B18: Nothing marked yet.
A20: Priority
A21: P1 | B21: Release blocker. Money, orders, stock, sign-in, security, data isolation, anything that returns an error page.
A22: P2 | B22: Should work. Fix before or soon after release.
A23: P3 | B23: Polish.
A25: Defect severity
A26: Blocker | B26: Cannot release: data loss, wrong money, security hole, cross-store data, page that errors.
A27: Major | B27: Feature broken and no workaround.
A28: Minor | B28: Workaround exists.
A29: Cosmetic | B29: Looks wrong, works fine.
A31: Environment (fill in)
A32: Build / commit under test
A33: Marketing URL
A34: Store URL
A35: Admin URL
A36: Platform admin URL
A37: Database / environment name
A38: Test date range
A39: Test store name
A40: Accounts used (emails only, no passwords)
A41: Devices and browsers
A43: Rules of thumb
A44: Use fresh data | B44: Each tester uses their own phone numbers and TrxIDs. A number may place only 3 storefront orders a day, and a TrxID works once.
A45: Money | B45: After every order, check the total by hand: items + delivery + COD fee - discounts. Never trust the screen alone.
A46: Stock | B46: After every order/cancel/return, check the stock number moved the right way.
...

Sheet Summary
A1: BizTrackBD QC / QA: summary
A2: Counts come from the Result column of every sheet. Nothing to type here.
A4: Sheet | B4: Checks | C4: Pass | D4: Fail | E4: Blocked | F4: In progress | G4: Not run | H4: N/A | I4: P1 checks | J4: P1 not passed | K4: % done (not 'Not run') | L4: % passed
A5: 1 Setup | B5: =COUNTA('1 Setup'!$A$4:$A$15) | C5: =COUNTIF('1 Setup'!$J$4:$J$15,"Pass") | D5: =COUNTIF('1 Setup'!$J$4:$J$15,"Fail") | E5: =COUNTIF('1 Setup'!$J$4:$J$15,"Blocked") | F5: =COUNTIF('1 Setup'!$J$4:$J$15,"In progress") | G5: =COUNTIF('1 Setup'!$J$4:$J$15,"Not run") | H5: =COUNTIF('1 Setup'!$J$4:$J$15,"N/A") | I5: =COUNTIF('1 Setup'!$B$4:$B$15,"P1") | J5: =COUNTIFS('1 Setup'!$B$4:$B$15,"P1",'1 Setup'!$J$4:$J$15,"<>Pass",'1 Setup'!$J$4:$J$15,"<>N/A") | K5: =IF(B5-H5=0,0,1-G5/(B5-H5)) | L5: =IF(B5-H5=0,0,C5/(B5-H5))
A6: 2 Marketing site | B6: =COUNTA('2 Marketing site'!$A$4:$A$32) | C6: =COUNTIF('2 Marketing site'!$J$4:$J$32,"Pass") | D6: =COUNTIF('2 Marketing site'!$J$4:$J$32,"Fail") | E6: =COUNTIF('2 Marketing site'!$J$4:$J$32,"Blocked") | F6: =COUNTIF('2 Marketing site'!$J$4:$J$32,"In progress") | G6: =COUNTIF('2 Marketing site'!$J$4:$J$32,"Not run") | H6: =COUNTIF('2 Marketing site'!$J$4:$J$32,"N/A") | I6: =COUNTIF('2 Marketing site'!$B$4:$B$32,"P1") | J6: =COUNTIFS('2 Marketing site'!$B$4:$B$32,"P1",'2 Marketing site'!$J$4:$J$32,"<>Pass",'2 Marketing site'!$J$4:$J$32,"<>N/A") | K6: =IF(B6-H6=0,0,1-G6/(B6-H6)) | L6: =IF(B6-H6=0,0,C6/(B6-H6))
A7: 3 Store browse | B7: =COUNTA('3 Store browse'!$A$4:$A$35) | C7: =COUNTIF('3 Store browse'!$J$4:$J$35,"Pass") | D7: =COUNTIF('3 Store browse'!$J$4:$J$35,"Fail") | E7: =COUNTIF('3 Store browse'!$J$4:$J$35,"Blocked") | F7: =COUNTIF('3 Store browse'!$J$4:$J$35,"In progress") | G7: =COUNTIF('3 Store browse'!$J$4:$J$35,"Not run") | H7: =COUNTIF('3 Store browse'!$J$4:$J$35,"N/A") | I7: =COUNTIF('3 Store browse'!$B$4:$B$35,"P1") | J7: =COUNTIFS('3 Store browse'!$B$4:$B$35,"P1",'3 Store browse'!$J$4:$J$35,"<>Pass",'3 Store browse'!$J$4:$J$35,"<>N/A") | K7: =IF(B7-H7=0,0,1-G7/(B7-H7)) | L7: =IF(B7-H7=0,0,C7/(B7-H7))
A8: 4 Cart & checkout | B8: =COUNTA('4 Cart & checkout'!$A$4:$A$39) | C8: =COUNTIF('4 Cart & checkout'!$J$4:$J$39,"Pass") | D8: =COUNTIF('4 Cart & checkout'!$J$4:$J$39,"Fail") | E8: =COUNTIF('4 Cart & checkout'!$J$4:$J$39,"Blocked") | F8: =COUNTIF('4 Cart & checkout'!$J$4:$J$39,"In progress") | G8: =COUNTIF('4 Cart & checkout'!$J$4:$J$39,"Not run") | H8: =COUNTIF('4 Cart & checkout'!$J$4:$J$39,"N/A") | I8: =COUNTIF('4 Cart & checkout'!$B$4:$B$39,"P1") | J8: =COUNTIFS('4 Cart & checkout'!$B$4:$B$39,"P1",'4 Cart & checkout'!$J$4:$J$39,"<>Pass",'4 Cart & checkout'!$J$4:$J$39,"<>N/A") | K8: =IF(B8-H8=0,0,1-G8/(B8-H8)) | L8: =IF(B8-H8=0,0,C8/(B8-H8))
A9: 5 Customer account | B9: =COUNTA('5 Customer account'!$A$4:$A$21) | C9: =COUNTIF('5 Customer account'!$J$4:$J$21,"Pass") | D9: =COUNTIF('5 Customer account'!$J$4:$J$21,"Fail") | E9: =COUNTIF('5 Customer account'!$J$4:$J$21,"Blocked") | F9: =COUNTIF('5 Customer account'!$J$4:$J$21,"In progress") | G9: =COUNTIF('5 Customer account'!$J$4:$J$21,"Not run") | H9: =COUNTIF('5 Customer account'!$J$4:$J$21,"N/A") | I9: =COUNTIF('5 Customer account'!$B$4:$B$21,"P1") | J9: =COUNTIFS('5 Customer account'!$B$4:$B$21,"P1",'5 Customer account'!$J$4:$J$21,"<>Pass",'5 Customer account'!$J$4:$J$21,"<>N/A") | K9: =IF(B9-H9=0,0,1-G9/(B9-H9)) | L9: =IF(B9-H9=0,0,C9/(B9-H9))
A10: 6 Admin access | B10: =COUNTA('6 Admin access'!$A$4:$A$22) | C10: =COUNTIF('6 Admin access'!$J$4:$J$22,"Pass") | D10: =COUNTIF('6 Admin access'!$J$4:$J$22,"Fail") | E10: =COUNTIF('6 Admin access'!$J$4:$J$22,"Blocked") | F10: =COUNTIF('6 Admin access'!$J$4:$J$22,"In progress") | G10: =COUNTIF('6 Admin access'!$J$4:$J$22,"Not run") | H10: =COUNTIF('6 Admin access'!$J$4:$J$22,"N/A") | I10: =COUNTIF('6 Admin access'!$B$4:$B$22,"P1") | J10: =COUNTIFS('6 Admin access'!$B$4:$B$22,"P1",'6 Admin access'!$J$4:$J$22,"<>Pass",'6 Admin access'!$J$4:$J$22,"<>N/A") | K10: =IF(B10-H10=0,0,1-G10/(B10-H10)) | L10: =IF(B10-H10=0,0,C10/(B10-H10))
A11: 7 Admin orders | B11: =COUNTA('7 Admin orders'!$A$4:$A$55) | C11: =COUNTIF('7 Admin orders'!$J$4:$J$55,"Pass") | D11: =COUNTIF('7 Admin orders'!$J$4:$J$55,"Fail") | E11: =COUNTIF('7 Admin orders'!$J$4:$J$55,"Blocked") | F11: =COUNTIF('7 Admin orders'!$J$4:$J$55,"In progress") | G11: =COUNTIF('7 Admin orders'!$J$4:$J$55,"Not run") | H11: =COUNTIF('7 Admin orders'!$J$4:$J$55,"N/A") | I11: =COUNTIF('7 Admin orders'!$B$4:$B$55,"P1") | J11: =COUNTIFS('7 Admin orders'!$B$4:$B$55,"P1",'7 Admin orders'!$J$4:$J$55,"<>Pass",'7 Admin orders'!$J$4:$J$55,"<>N/A") | K11: =IF(B11-H11=0,0,1-G11/(B11-H11)) | L11: =IF(B11-H11=0,0,C11/(B11-H11))
A12: 8 Catalog & stock | B12: =COUNTA('8 Catalog & stock'!$A$4:$A$29) | C12: =COUNTIF('8 Catalog & stock'!$J$4:$J$29,"Pass") | D12: =COUNTIF('8 Catalog & stock'!$J$4:$J$29,"Fail") | E12: =COUNTIF('8 Catalog & stock'!$J$4:$J$29,"Blocked") | F12: =COUNTIF('8 Catalog & stock'!$J$4:$J$29,"In progress") | G12: =COUNTIF('8 Catalog & stock'!$J$4:$J$29,"Not run") | H12: =COUNTIF('8 Catalog & stock'!$J$4:$J$29,"N/A") | I12: =COUNTIF('8 Catalog & stock'!$B$4:$B$29,"P1") | J12: =COUNTIFS('8 Catalog & stock'!$B$4:$B$29,"P1",'8 Catalog & stock'!$J$4:$J$29,"<>Pass",'8 Catalog & stock'!$J$4:$J$29,"<>N/A") | K12: =IF(B12-H12=0,0,1-G12/(B12-H12)) | L12: =IF(B12-H12=0,0,C12/(B12-H12))
A13: 9 Customers & inbox | B13: =COUNTA('9 Customers & inbox'!$A$4:$A$16) | C13: =COUNTIF('9 Customers & inbox'!$J$4:$J$16,"Pass") | D13: =COUNTIF('9 Customers & inbox'!$J$4:$J$16,"Fail") | E13: =COUNTIF('9 Customers & inbox'!$J$4:$J$16,"Blocked") | F13: =COUNTIF('9 Customers & inbox'!$J$4:$J$16,"In progress") | G13: =COUNTIF('9 Customers & inbox'!$J$4:$J$16,"Not run") | H13: =COUNTIF('9 Customers & inbox'!$J$4:$J$16,"N/A") | I13: =COUNTIF('9 Customers & inbox'!$B$4:$B$16,"P1") | J13: =COUNTIFS('9 Customers & inbox'!$B$4:$B$16,"P1",'9 Customers & inbox'!$J$4:$J$16,"<>Pass",'9 Customers & inbox'!$J$4:$J$16,"<>N/A") | K13: =IF(B13-H13=0,0,1-G13/(B13-H13)) | L13: =IF(B13-H13=0,0,C13/(B13-H13))
A14: 10 Marketing & growth | B14: =COUNTA('10 Marketing & growth'!$A$4:$A$18) | C14: =COUNTIF('10 Marketing & growth'!$J$4:$J$18,"Pass") | D14: =COUNTIF('10 Marketing & growth'!$J$4:$J$18,"Fail") | E14: =COUNTIF('10 Marketing & growth'!$J$4:$J$18,"Blocked") | F14: =COUNTIF('10 Marketing & growth'!$J$4:$J$18,"In progress") | G14: =COUNTIF('10 Marketing & growth'!$J$4:$J$18,"Not run") | H14: =COUNTIF('10 Marketing & growth'!$J$4:$J$18,"N/A") | I14: =COUNTIF('10 Marketing & growth'!$B$4:$B$18,"P1") | J14: =COUNTIFS('10 Marketing & growth'!$B$4:$B$18,"P1",'10 Marketing & growth'!$J$4:$J$18,"<>Pass",'10 Marketing & growth'!$J$4:$J$18,"<>N/A") | K14: =IF(B14-H14=0,0,1-G14/(B14-H14)) | L14: =IF(B14-H14=0,0,C14/(B14-H14))
A15: 11 Money & reports | B15: =COUNTA('11 Money & reports'!$A$4:$A$15) | C15: =COUNTIF('11 Money & reports'!$J$4:$J$15,"Pass") | D15: =COUNTIF('11 Money & reports'!$J$4:$J$15,"Fail") | E15: =COUNTIF('11 Money & reports'!$J$4:$J$15,"Blocked") | F15: =COUNTIF('11 Money & reports'!$J$4:$J$15,"In progress") | G15: =COUNTIF('11 Money & reports'!$J$4:$J$15,"Not run") | H15: =COUNTIF('11 Money & reports'!$J$4:$J$15,"N/A") | I15: =COUNTIF('11 Money & reports'!$B$4:$B$15,"P1") | J15: =COUNTIFS('11 Money & reports'!$B$4:$B$15,"P1",'11 Money & reports'!$J$4:$J$15,"<>Pass",'11 Money & reports'!$J$4:$J$15,"<>N/A") | K15: =IF(B15-H15=0,0,1-G15/(B15-H15)) | L15: =IF(B15-H15=0,0,C15/(B15-H15))
A16: 12 Store design | B16: =COUNTA('12 Store design'!$A$4:$A$14) | C16: =COUNTIF('12 Store design'!$J$4:$J$14,"Pass") | D16: =COUNTIF('12 Store design'!$J$4:$J$14,"Fail") | E16: =COUNTIF('12 Store design'!$J$4:$J$14,"Blocked") | F16: =COUNTIF('12 Store design'!$J$4:$J$14,"In progress") | G16: =COUNTIF('12 Store design'!$J$4:$J$14,"Not run") | H16: =COUNTIF('12 Store design'!$J$4:$J$14,"N/A") | I16: =COUNTIF('12 Store design'!$B$4:$B$14,"P1") | J16: =COUNTIFS('12 Store design'!$B$4:$B$14,"P1",'12 Store design'!$J$4:$J$14,"<>Pass",'12 Store design'!$J$4:$J$14,"<>N/A") | K16: =IF(B16-H16=0,0,1-G16/(B16-H16)) | L16: =IF(B16-H16=0,0,C16/(B16-H16))
A17: 13 Settings & team | B17: =COUNTA('13 Settings & team'!$A$4:$A$18) | C17: =COUNTIF('13 Settings & team'!$J$4:$J$18,"Pass") | D17: =COUNTIF('13 Settings & team'!$J$4:$J$18,"Fail") | E17: =COUNTIF('13 Settings & team'!$J$4:$J$18,"Blocked") | F17: =COUNTIF('13 Settings & team'!$J$4:$J$18,"In progress") | G17: =COUNTIF('13 Settings & team'!$J$4:$J$18,"Not run") | H17: =COUNTIF('13 Settings & team'!$J$4:$J$18,"N/A") | I17: =COUNTIF('13 Settings & team'!$B$4:$B$18,"P1") | J17: =COUNTIFS('13 Settings & team'!$B$4:$B$18,"P1",'13 Settings & team'!$J$4:$J$18,"<>Pass",'13 Settings & team'!$J$4:$J$18,"<>N/A") | K17: =IF(B17-H17=0,0,1-G17/(B17-H17)) | L17: =IF(B17-H17=0,0,C17/(B17-H17))
A18: 14 Platform admin | B18: =COUNTA('14 Platform admin'!$A$4:$A$23) | C18: =COUNTIF('14 Platform admin'!$J$4:$J$23,"Pass") | D18: =COUNTIF('14 Platform admin'!$J$4:$J$23,"Fail") | E18: =COUNTIF('14 Platform admin'!$J$4:$J$23,"Blocked") | F18: =COUNTIF('14 Platform admin'!$J$4:$J$23,"In progress") | G18: =COUNTIF('14 Platform admin'!$J$4:$J$23,"Not run") | H18: =COUNTIF('14 Platform admin'!$J$4:$J$23,"N/A") | I18: =COUNTIF('14 Platform admin'!$B$4:$B$23,"P1") | J18: =COUNTIFS('14 Platform admin'!$B$4:$B$23,"P1",'14 Platform admin'!$J$4:$J$23,"<>Pass",'14 Platform admin'!$J$4:$J$23,"<>N/A") | K18: =IF(B18-H18=0,0,1-G18/(B18-H18)) | L18: =IF(B18-H18=0,0,C18/(B18-H18))
A19: 15 Roles matrix | B19: =COUNTA('15 Roles matrix'!$A$4:$A$43) | C19: =COUNTIF('15 Roles matrix'!$J$4:$J$43,"Pass") | D19: =COUNTIF('15 Roles matrix'!$J$4:$J$43,"Fail") | E19: =COUNTIF('15 Roles matrix'!$J$4:$J$43,"Blocked") | F19: =COUNTIF('15 Roles matrix'!$J$4:$J$43,"In progress") | G19: =COUNTIF('15 Roles matrix'!$J$4:$J$43,"Not run") | H19: =COUNTIF('15 Roles matrix'!$J$4:$J$43,"N/A") | I19: =COUNTIF('15 Roles matrix'!$B$4:$B$43,"P1") | J19: =COUNTIFS('15 Roles matrix'!$B$4:$B$43,"P1",'15 Roles matrix'!$J$4:$J$43,"<>Pass",'15 Roles matrix'!$J$4:$J$43,"<>N/A") | K19: =IF(B19-H19=0,0,1-G19/(B19-H19)) | L19: =IF(B19-H19=0,0,C19/(B19-H19))
A20: 16 Security & privacy | B20: =COUNTA('16 Security & privacy'!$A$4:$A$24) | C20: =COUNTIF('16 Security & privacy'!$J$4:$J$24,"Pass") | D20: =COUNTIF('16 Security & privacy'!$J$4:$J$24,"Fail") | E20: =COUNTIF('16 Security & privacy'!$J$4:$J$24,"Blocked") | F20: =COUNTIF('16 Security & privacy'!$J$4:$J$24,"In progress") | G20: =COUNTIF('16 Security & privacy'!$J$4:$J$24,"Not run") | H20: =COUNTIF('16 Security & privacy'!$J$4:$J$24,"N/A") | I20: =COUNTIF('16 Security & privacy'!$B$4:$B$24,"P1") | J20: =COUNTIFS('16 Security & privacy'!$B$4:$B$24,"P1",'16 Security & privacy'!$J$4:$J$24,"<>Pass",'16 Security & privacy'!$J$4:$J$24,"<>N/A") | K20: =IF(B20-H20=0,0,1-G20/(B20-H20)) | L20: =IF(B20-H20=0,0,C20/(B20-H20))
A21: 17 Quality | B21: =COUNTA('17 Quality'!$A$4:$A$23) | C21: =COUNTIF('17 Quality'!$J$4:$J$23,"Pass") | D21: =COUNTIF('17 Quality'!$J$4:$J$23,"Fail") | E21: =COUNTIF('17 Quality'!$J$4:$J$23,"Blocked") | F21: =COUNTIF('17 Quality'!$J$4:$J$23,"In progress") | G21: =COUNTIF('17 Quality'!$J$4:$J$23,"Not run") | H21: =COUNTIF('17 Quality'!$J$4:$J$23,"N/A") | I21: =COUNTIF('17 Quality'!$B$4:$B$23,"P1") | J21: =COUNTIFS('17 Quality'!$B$4:$B$23,"P1",'17 Quality'!$J$4:$J$23,"<>Pass",'17 Quality'!$J$4:$J$23,"<>N/A") | K21: =IF(B21-H21=0,0,1-G21/(B21-H21)) | L21: =IF(B21-H21=0,0,C21/(B21-H21))
A22: 18 Integrations | B22: =COUNTA('18 Integrations'!$A$4:$A$19) | C22: =COUNTIF('18 Integrations'!$J$4:$J$19,"Pass") | D22: =COUNTIF('18 Integrations'!$J$4:$J$19,"Fail") | E22: =COUNTIF('18 Integrations'!$J$4:$J$19,"Blocked") | F22: =COUNTIF('18 Integrations'!$J$4:$J$19,"In progress") | G22: =COUNTIF('18 Integrations'!$J$4:$J$19,"Not run") | H22: =COUNTIF('18 Integrations'!$J$4:$J$19,"N/A") | I22: =COUNTIF('18 Integrations'!$B$4:$B$19,"P1") | J22: =COUNTIFS('18 Integrations'!$B$4:$B$19,"P1",'18 Integrations'!$J$4:$J$19,"<>Pass",'18 Integrations'!$J$4:$J$19,"<>N/A") | K22: =IF(B22-H22=0,0,1-G22/(B22-H22)) | L22: =IF(B22-H22=0,0,C22/(B22-H22))
A23: 19 Smoke (30 min) | B23: =COUNTA('19 Smoke (30 min)'!$A$4:$A$20) | C23: =COUNTIF('19 Smoke (30 min)'!$J$4:$J$20,"Pass") | D23: =COUNTIF('19 Smoke (30 min)'!$J$4:$J$20,"Fail") | E23: =COUNTIF('19 Smoke (30 min)'!$J$4:$J$20,"Blocked") | F23: =COUNTIF('19 Smoke (30 min)'!$J$4:$J$20,"In progress") | G23: =COUNTIF('19 Smoke (30 min)'!$J$4:$J$20,"Not run") | H23: =COUNTIF('19 Smoke (30 min)'!$J$4:$J$20,"N/A") | I23: =COUNTIF('19 Smoke (30 min)'!$B$4:$B$20,"P1") | J23: =COUNTIFS('19 Smoke (30 min)'!$B$4:$B$20,"P1",'19 Smoke (30 min)'!$J$4:$J$20,"<>Pass",'19 Smoke (30 min)'!$J$4:$J$20,"<>N/A") | K23: =IF(B23-H23=0,0,1-G23/(B23-H23)) | L23: =IF(B23-H23=0,0,C23/(B23-H23))
A24: 20 Release & sign-off | B24: =COUNTA('20 Release & sign-off'!$A$4:$A$14) | C24: =COUNTIF('20 Release & sign-off'!$J$4:$J$14,"Pass") | D24: =COUNTIF('20 Release & sign-off'!$J$4:$J$14,"Fail") | E24: =COUNTIF('20 Release & sign-off'!$J$4:$J$14,"Blocked") | F24: =COUNTIF('20 Release & sign-off'!$J$4:$J$14,"In progress") | G24: =COUNTIF('20 Release & sign-off'!$J$4:$J$14,"Not run") | H24: =COUNTIF('20 Release & sign-off'!$J$4:$J$14,"N/A") | I24: =COUNTIF('20 Release & sign-off'!$B$4:$B$14,"P1") | J24: =COUNTIFS('20 Release & sign-off'!$B$4:$B$14,"P1",'20 Release & sign-off'!$J$4:$J$14,"<>Pass",'20 Release & sign-off'!$J$4:$J$14,"<>N/A") | K24: =IF(B24-H24=0,0,1-G24/(B24-H24)) | L24: =IF(B24-H24=0,0,C24/(B24-H24))
A25: TOTAL | B25: =SUM(B5:B24) | C25: =SUM(C5:C24) | D25: =SUM(D5:D24) | E25: =SUM(E5:E24) | F25: =SUM(F5:F24) | G25: =SUM(G5:G24) | H25: =SUM(H5:H24) | I25: =SUM(I5:I24) | J25: =SUM(J5:J24) | K25: =IF(B25-H25=0,0,1-G25/(B25-H25)) | L25: =IF(B25-H25=0,0,C25/(B25-H25))
A27: Open defects (not verified / closed) | B27: =COUNTA('21 Defect log'!G4:G203)-COUNTIF('21 Defect log'!M4:M203,"Verified")-COUNTIF('21 Defect log'!M4:M203,"Won't fix")-COUNTIF('21 Defect log'!M4:M203,"Duplicate")
A28: of which Blocker | B28: =COUNTIFS('21 Defect log'!F4:F203,"Blocker",'21 Defect log'!M4:M203,"<>Verified",'21 Defect log'!M4:M203,"<>Won't fix",'21 Defect log'!M4:M203,"<>Duplicate")
A29: of which Major | B29: =COUNTIFS('21 Defect log'!F4:F203,"Major",'21 Defect log'!M4:M203,"<>Verified",'21 Defect log'!M4:M203,"<>Won't fix",'21 Defect log'!M4:M203,"<>Duplicate")
A31: Release recommendation | B31: =IF(OR(J25>0,B28>0),"NOT READY: P1 checks not passed or a Blocker is open",IF(G25>0,"NOT READY: checks not yet run","READY: all P1 passed, nothing blocking"))

Sheet 1 Setup
A1: Setup and environment (do this first)
A2: Mark Phone and Desktop with Pass / Fail / Blocked / N/A. Result fills itself. P1 = release blocker, P2 = should work, P3 = polish.
A3: ID | B3: Priority | C3: Role | D3: Where | E3: Check | F3: Steps | G3: Expected result | H3: Phone 390px | I3: Desktop 1440px | J3: Result | K3: Tester | L3: Date | M3: Bug ref / notes
A4: SET-01 | B4: P1 | C4: QA lead | D4: Environment | E4: Test environment is identified | F4: Write down the URLs: marketing, store (e.g. demo.<root>), admin, platform admin. | G4: All four URLs recorded on the Read Me sheet. | J4: =IF(OR(H4="Fail",I4="Fail"),"Fail",IF(OR(H4="Blocked",I4="Blocked"),"Blocked",IF(AND(OR(H4="Pass",H4="N/A"),OR(I4="Pass",I4="N/A"),COUNTIF(H4:I4,"Pass")>0),"Pass",IF(AND(H4="N/A",I4="N/A"),"N/A",IF(COUNTA(H4:I4)=0,"Not run","In progress")))))
A5: SET-02 | B5: P1 | C5: QA lead | D5: Database | E5: All database migrations are applied | F5: GitHub > Actions > Migrations > latest run. | G5: Run is green and says 'All N migrations are applied'. | J5: =IF(OR(H5="Fail",I5="Fail"),"Fail",IF(OR(H5="Blocked",I5="Blocked"),"Blocked",IF(AND(OR(H5="Pass",H5="N/A"),OR(I5="Pass",I5="N/A"),COUNTIF(H5:I5,"Pass")>0),"Pass",IF(AND(H5="N/A",I5="N/A"),"N/A",IF(COUNTA(H5:I5)=0,"Not run","In progress")))))
A6: SET-03 | B6: P1 | C6: QA lead | D6: Database | E6: Latest deployment is the commit under test | F6: Vercel > Deployments for each app. | G6: All apps show READY for the same commit; no failed build. | J6: =IF(OR(H6="Fail",I6="Fail"),"Fail",IF(OR(H6="Blocked",I6="Blocked"),"Blocked",IF(AND(OR(H6="Pass",H6="N/A"),OR(I6="Pass",I6="N/A"),COUNTIF(H6:I6,"Pass")>0),"Pass",IF(AND(H6="N/A",I6="N/A"),"N/A",IF(COUNTA(H6:I6)=0,"Not run","In progress")))))
A7: SET-04 | B7: P1 | C7: QA lead | D7: Config | E7: Server secrets are set | F7: Check Vercel env: CRON_SECRET, CUSTOMER_AUTH_SECRET, INTEGRATION_VAULT_SECRET, PREVIEW_SECRET, PHONE_TRUST_SALT, SMS provider key, Supabase keys. | G7: No secret missing; nothing placeholder. | J7: =IF(OR(H7="Fail",I7="Fail"),"Fail",IF(OR(H7="Blocked",I7="Blocked"),"Blocked",IF(AND(OR(H7="Pass",H7="N/A"),OR(I7="Pass",I7="N/A"),COUNTIF(H7:I7,"Pass")>0),"Pass",IF(AND(H7="N/A",I7="N/A"),"N/A",IF(COUNTA(H7:I7)=0,"Not run","In progress")))))
A8: SET-05 | B8: P1 | C8: Platform owner | D8: Config | E8: Fraud checker key is entered | F8: Platform admin > Settings > Fraud checker. Paste key, press Test. | G8: Test says 'The key works'. Active key shows masked. | J8: =IF(OR(H8="Fail",I8="Fail"),"Fail",IF(OR(H8="Blocked",I8="Blocked"),"Blocked",IF(AND(OR(H8="Pass",H8="N/A"),OR(I8="Pass",I8="N/A"),COUNTIF(H8:I8,"Pass")>0),"Pass",IF(AND(H8="N/A",I8="N/A"),"N/A",IF(COUNTA(H8:I8)=0,"Not run","In progress")))))
A9: SET-06 | B9: P2 | C9: QA lead | D9: Config | E9: Cron jobs are scheduled | F9: Check scheduler for /api/cron/abandoned, /api/cron/stock-alerts, /api/cron/courier-sync, /api/cron/loyalty, /api/cron/domains, /api/cron/billing. | G9: Each is scheduled with the Authorization: Bearer CRON_SECRET header. | J9: =IF(OR(H9="Fail",I9="Fail"),"Fail",IF(OR(H9="Blocked",I9="Blocked"),"Blocked",IF(AND(OR(H9="Pass",H9="N/A"),OR(I9="Pass",I9="N/A"),COUNTIF(H9:I9,"Pass")>0),"Pass",IF(AND(H9="N/A",I9="N/A"),"N/A",IF(COUNTA(H9:I9)=0,"Not run","In progress")))))
A10: SET-07 | B10: P1 | C10: QA lead | D10: Accounts | E10: Test accounts exist for every role | F10: Create: store owner, manager, packer (order packer), support (telemarketer), content editor; platform owner, finance, support lead, support. | G10: Each can sign in. Write the emails (not passwords) on the Read Me sheet. | J10: =IF(OR(H10="Fail",I10="Fail"),"Fail",IF(OR(H10="Blocked",I10="Blocked"),"Blocked",IF(AND(OR(H10="Pass",H10="N/A"),OR(I10="Pass",I10="N/A"),COUNTIF(H10:I10,"Pass")>0),"Pass",IF(AND(H10="N/A",I10="N/A"),"N/A",IF(COUNTA(H10:I10)=0,"Not run","In progress")))))
A11: SET-08 | B11: P1 | C11: QA lead | D11: Test data | E11: A test store exists with sample data | F11: At least: 6 products (one with sizes, one sold out), 3 categories (one sub-category), 3 shipping zones, a coupon, bKash and Nagad numbers set, COD on. | G11: Store opens on its address with products visible. | J11: =IF(OR(H11="Fail",I11="Fail"),"Fail",IF(OR(H11="Blocked",I11="Blocked"),"Blocked",IF(AND(OR(H11="Pass",H11="N/A"),OR(I11="Pass",I11="N/A"),COUNTIF(H11:I11,"Pass")>0),"Pass",IF(AND(H11="N/A",I11="N/A"),"N/A",IF(COUNTA(H11:I11)=0,"Not run","In progress")))))
A12: SET-09 | B12: P2 | C12: QA lead | D12: Test data | E12: Test phones and bKash/Nagad TrxIDs ready | F12: Prepare 6 fresh BD mobile numbers (01XXXXXXXXX) and 6 unused 8-12 character TrxIDs. | G12: Numbers are valid; none used by an earlier test day (limit: 3 storefront orders per phone per day). | J12: =IF(OR(H12="Fail",I12="Fail"),"Fail",IF(OR(H12="Blocked",I12="Blocked"),"Blocked",IF(AND(OR(H12="Pass",H12="N/A"),OR(I12="Pass",I12="N/A"),COUNTIF(H12:I12,"Pass")>0),"Pass",IF(AND(H12="N/A",I12="N/A"),"N/A",IF(COUNTA(H12:I12)=0,"Not run","In progress")))))
A13: SET-10 | B13: P2 | C13: QA lead | D13: Test data | E13: Courier test accounts | F13: Steadfast, Pathao, RedX sandbox/live keys saved in Admin > Settings > Apps. | G13: Each shows Connected; test button passes. | J13: =IF(OR(H13="Fail",I13="Fail"),"Fail",IF(OR(H13="Blocked",I13="Blocked"),"Blocked",IF(AND(OR(H13="Pass",H13="N/A"),OR(I13="Pass",I13="N/A"),COUNTIF(H13:I13,"Pass")>0),"Pass",IF(AND(H13="N/A",I13="N/A"),"N/A",IF(COUNTA(H13:I13)=0,"Not run","In progress")))))
A14: SET-11 | B14: P2 | C14: QA lead | D14: Devices | E14: Devices and browsers listed | F14: Phone 390px wide (real Android + iPhone if possible), desktop 1440px, Chrome, Safari, Firefox, Edge. | G14: List recorded on the Read Me sheet. | J14: =IF(OR(H14="Fail",I14="Fail"),"Fail",IF(OR(H14="Blocked",I14="Blocked"),"Blocked",IF(AND(OR(H14="Pass",H14="N/A"),OR(I14="Pass",I14="N/A"),COUNTIF(H14:I14,"Pass")>0),"Pass",IF(AND(H14="N/A",I14="N/A"),"N/A",IF(COUNTA(H14:I14)=0,"Not run","In progress")))))
A15: SET-12 | B15: P2 | C15: QA lead | D15: Backup | E15: A backup exists before testing on production | F15: Check the latest Backup workflow run. | G15: Green run within 24 hours. | J15: =IF(OR(H15="Fail",I15="Fail"),"Fail",IF(OR(H15="Blocked",I15="Blocked"),"Blocked",IF(AND(OR(H15="Pass",H15="N/A"),OR(I15="Pass",I15="N/A"),COUNTIF(H15:I15,"Pass")>0),"Pass",IF(AND(H15="N/A",I15="N/A"),"N/A",IF(COUNTA(H15:I15)=0,"Not run","In progress")))))

Sheet 2 Marketing site
A1: Marketing website
A2: Mark Phone and Desktop with Pass / Fail / Blocked / N/A. Result fills itself. P1 = release blocker, P2 = should work, P3 = polish.
A3: ID | B3: Priority | C3: Role | D3: Where | E3: Check | F3: Steps | G3: Expected result | H3: Phone 390px | I3: Desktop 1440px | J3: Result | K3: Tester | L3: Date | M3: Bug ref / notes
A4: MKT-01 | B4: P1 | C4: Visitor | D4: / | E4: Home page loads | F4: Open the marketing home on phone and desktop. | G4: Page loads under 3 s, no errors, hero, CTA 'Open a free store' visible. | J4: =IF(OR(H4="Fail",I4="Fail"),"Fail",IF(OR(H4="Blocked",I4="Blocked"),"Blocked",IF(AND(OR(H4="Pass",H4="N/A"),OR(I4="Pass",I4="N/A"),COUNTIF(H4:I4,"Pass")>0),"Pass",IF(AND(H4="N/A",I4="N/A"),"N/A",IF(COUNTA(H4:I4)=0,"Not run","In progress")))))
A5: MKT-02 | B5: P1 | C5: Visitor | D5: / | E5: Primary call-to-action works | F5: Click the main signup button. | G5: Goes to /start (signup). | J5: =IF(OR(H5="Fail",I5="Fail"),"Fail",IF(OR(H5="Blocked",I5="Blocked"),"Blocked",IF(AND(OR(H5="Pass",H5="N/A"),OR(I5="Pass",I5="N/A"),COUNTIF(H5:I5,"Pass")>0),"Pass",IF(AND(H5="N/A",I5="N/A"),"N/A",IF(COUNTA(H5:I5)=0,"Not run","In progress")))))
A6: MKT-03 | B6: P2 | C6: Visitor | D6: / | E6: Navigation and footer links | F6: Click every header and footer link. | G6: No 404. Links open the right page. Privacy and Terms linked in footer. | J6: =IF(OR(H6="Fail",I6="Fail"),"Fail",IF(OR(H6="Blocked",I6="Blocked"),"Blocked",IF(AND(OR(H6="Pass",H6="N/A"),OR(I6="Pass",I6="N/A"),COUNTIF(H6:I6,"Pass")>0),"Pass",IF(AND(H6="N/A",I6="N/A"),"N/A",IF(COUNTA(H6:I6)=0,"Not run","In progress")))))
A7: MKT-04 | B7: P2 | C7: Visitor | D7: / | E7: Language | F7: Check Bangla and English text where offered. | G7: Bangla renders with correct font; no broken characters. | J7: =IF(OR(H7="Fail",I7="Fail"),"Fail",IF(OR(H7="Blocked",I7="Blocked"),"Blocked",IF(AND(OR(H7="Pass",H7="N/A"),OR(I7="Pass",I7="N/A"),COUNTIF(H7:I7,"Pass")>0),"Pass",IF(AND(H7="N/A",I7="N/A"),"N/A",IF(COUNTA(H7:I7)=0,"Not run","In progress")))))
A8: MKT-05 | B8: P2 | C8: Visitor | D8: /features | E8: Features page | F8: Open /features. | G8: All feature sections show; images load; no layout break at 390px. | J8: =IF(OR(H8="Fail",I8="Fail"),"Fail",IF(OR(H8="Blocked",I8="Blocked"),"Blocked",IF(AND(OR(H8="Pass",H8="N/A"),OR(I8="Pass",I8="N/A"),COUNTIF(H8:I8,"Pass")>0),"Pass",IF(AND(H8="N/A",I8="N/A"),"N/A",IF(COUNTA(H8:I8)=0,"Not run","In progress")))))
A9: MKT-06 | B9: P1 | C9: Visitor | D9: /pricing | E9: Plans and prices are correct | F9: Compare each plan card with the Platform admin > Plans values. | G9: Same names, monthly and yearly prices, limits and features. | J9: =IF(OR(H9="Fail",I9="Fail"),"Fail",IF(OR(H9="Blocked",I9="Blocked"),"Blocked",IF(AND(OR(H9="Pass",H9="N/A"),OR(I9="Pass",I9="N/A"),COUNTIF(H9:I9,"Pass")>0),"Pass",IF(AND(H9="N/A",I9="N/A"),"N/A",IF(COUNTA(H9:I9)=0,"Not run","In progress")))))
A10: MKT-07 | B10: P2 | C10: Visitor | D10: /pricing | E10: Monthly / yearly toggle | F10: Switch the toggle. | G10: Prices and 'save' text update correctly. | J10: =IF(OR(H10="Fail",I10="Fail"),"Fail",IF(OR(H10="Blocked",I10="Blocked"),"Blocked",IF(AND(OR(H10="Pass",H10="N/A"),OR(I10="Pass",I10="N/A"),COUNTIF(H10:I10,"Pass")>0),"Pass",IF(AND(H10="N/A",I10="N/A"),"N/A",IF(COUNTA(H10:I10)=0,"Not run","In progress")))))
A11: MKT-08 | B11: P2 | C11: Visitor | D11: /pricing | E11: Plan buttons | F11: Click each plan's button. | G11: Goes to /start with the plan chosen. | J11: =IF(OR(H11="Fail",I11="Fail"),"Fail",IF(OR(H11="Blocked",I11="Blocked"),"Blocked",IF(AND(OR(H11="Pass",H11="N/A"),OR(I11="Pass",I11="N/A"),COUNTIF(H11:I11,"Pass")>0),"Pass",IF(AND(H11="N/A",I11="N/A"),"N/A",IF(COUNTA(H11:I11)=0,"Not run","In progress")))))
A12: MKT-09 | B12: P2 | C12: Visitor | D12: /templates | E12: Template gallery | F12: Open /templates; open a template preview. | G12: Previews load in the store theme; back button returns. | J12: =IF(OR(H12="Fail",I12="Fail"),"Fail",IF(OR(H12="Blocked",I12="Blocked"),"Blocked",IF(AND(OR(H12="Pass",H12="N/A"),OR(I12="Pass",I12="N/A"),COUNTIF(H12:I12,"Pass")>0),"Pass",IF(AND(H12="N/A",I12="N/A"),"N/A",IF(COUNTA(H12:I12)=0,"Not run","In progress")))))
A13: MKT-10 | B13: P3 | C13: Visitor | D13: /compare | E13: Comparison page | F13: Open /compare. | G13: Table readable on phone (scrolls inside its box, not the page). | J13: =IF(OR(H13="Fail",I13="Fail"),"Fail",IF(OR(H13="Blocked",I13="Blocked"),"Blocked",IF(AND(OR(H13="Pass",H13="N/A"),OR(I13="Pass",I13="N/A"),COUNTIF(H13:I13,"Pass")>0),"Pass",IF(AND(H13="N/A",I13="N/A"),"N/A",IF(COUNTA(H13:I13)=0,"Not run","In progress")))))
A14: MKT-11 | B14: P2 | C14: Visitor | D14: /couriers | E14: Couriers page | F14: Open /couriers. | G14: Steadfast, Pathao, RedX instructions show; no broken links. | J14: =IF(OR(H14="Fail",I14="Fail"),"Fail",IF(OR(H14="Blocked",I14="Blocked"),"Blocked",IF(AND(OR(H14="Pass",H14="N/A"),OR(I14="Pass",I14="N/A"),COUNTIF(H14:I14,"Pass")>0),"Pass",IF(AND(H14="N/A",I14="N/A"),"N/A",IF(COUNTA(H14:I14)=0,"Not run","In progress")))))
A15: MKT-12 | B15: P2 | C15: Visitor | D15: /migrate | E15: Migration page | F15: Open /migrate. | G15: Explains import from Shopify/WooCommerce; links to signup. | J15: =IF(OR(H15="Fail",I15="Fail"),"Fail",IF(OR(H15="Blocked",I15="Blocked"),"Blocked",IF(AND(OR(H15="Pass",H15="N/A"),OR(I15="Pass",I15="N/A"),COUNTIF(H15:I15,"Pass")>0),"Pass",IF(AND(H15="N/A",I15="N/A"),"N/A",IF(COUNTA(H15:I15)=0,"Not run","In progress")))))
... A32: MKT-29 | B32: P3 | C32: Visitor | D32: All pages | E32: Accessibility basics | F32: Tab through the home page; zoom to 200%. | G32: Focus visible, no content cut off. | J32: =IF(OR(H32="Fail",I32="Fail"),"Fail",IF(OR(H32="Blocked",I32="Blocked"),"Blocked",IF(AND(OR(H32="Pass",H32="N/A"),OR(I32="Pass",I32="N/A"),COUNTIF(H32:I32,"Pass")>0),"Pass",IF(AND(H32="N/A",I32="N/A"),"N/A",IF(COUNTA(H32:I32)=0,"Not run","In progress")))))

Sheet 3 Store browse
A1: Storefront: browsing and product pages
A2: Mark Phone and Desktop with Pass / Fail / Blocked / N/A. Result fills itself. P1 = release blocker, P2 = should work, P3 = polish.
A3: ID | B3: Priority | C3: Role | D3: Where | E3: Check | F3: Steps | G3: Expected result | H3: Phone 390px | I3: Desktop 1440px | J3: Result | K3: Tester | L3: Date | M3: Bug ref / notes
A4: STB-01 | B4: P1 | C4: Customer | D4: / | E4: Home page loads | F4: Open the store address. | G4: Hero, new arrivals, categories, trust strip show. Under 3 s on 4G. | J4: =IF(OR(H4="Fail",I4="Fail"),"Fail",IF(OR(H4="Blocked",I4="Blocked"),"Blocked",IF(AND(OR(H4="Pass",H4="N/A"),OR(I4="Pass",I4="N/A"),COUNTIF(H4:I4,"Pass")>0),"Pass",IF(AND(H4="N/A",I4="N/A"),"N/A",IF(COUNTA(H4:I4)=0,"Not run","In progress")))))
A5: STB-02 | B5: P1 | C5: Customer | D5: / | E5: Store identity | F5: Check logo/name, announcement bar, colours. | G5: Match Admin > Settings > Store details and Store design. | J5: =IF(OR(H5="Fail",I5="Fail"),"Fail",IF(OR(H5="Blocked",I5="Blocked"),"Blocked",IF(AND(OR(H5="Pass",H5="N/A"),OR(I5="Pass",I5="N/A"),COUNTIF(H5:I5,"Pass")>0),"Pass",IF(AND(H5="N/A",I5="N/A"),"N/A",IF(COUNTA(H5:I5)=0,"Not run","In progress")))))
A6: STB-03 | B6: P2 | C6: Customer | D6: / | E6: Language switch | F6: Switch English <-> Bangla. | G6: All page text and digits switch; choice is remembered after reload. | J6: =IF(OR(H6="Fail",I6="Fail"),"Fail",IF(OR(H6="Blocked",I6="Blocked"),"Blocked",IF(AND(OR(H6="Pass",H6="N/A"),OR(I6="Pass",I6="N/A"),COUNTIF(H6:I6,"Pass")>0),"Pass",IF(AND(H6="N/A",I6="N/A"),"N/A",IF(COUNTA(H6:I6)=0,"Not run","In progress")))))
A7: STB-04 | B7: P2 | C7: Customer | D7: / | E7: Header on phone and desktop | F7: Check the menu button (phone) and nav (desktop), search, account and cart icons. | G7: All reachable; cart count updates. | J7: =IF(OR(H7="Fail",I7="Fail"),"Fail",IF(OR(H7="Blocked",I7="Blocked"),"Blocked",IF(AND(OR(H7="Pass",H7="N/A"),OR(I7="Pass",I7="N/A"),COUNTIF(H7:I7,"Pass")>0),"Pass",IF(AND(H7="N/A",I7="N/A"),"N/A",IF(COUNTA(H7:I7)=0,"Not run","In progress")))))
A8: STB-05 | B8: P2 | C8: Customer | D8: Footer | E8: Footer content | F8: Check phone, WhatsApp, Facebook, pages, Contact link, platform credit. | G8: Links work; Contact opens /contact; no overlap with WhatsApp button. | J8: =IF(OR(H8="Fail",I8="Fail"),"Fail",IF(OR(H8="Blocked",I8="Blocked"),"Blocked",IF(AND(OR(H8="Pass",H8="N/A"),OR(I8="Pass",I8="N/A"),COUNTIF(H8:I8,"Pass")>0),"Pass",IF(AND(H8="N/A",I8="N/A"),"N/A",IF(COUNTA(H8:I8)=0,"Not run","In progress")))))
A9: STB-06 | B9: P2 | C9: Customer | D9: WhatsApp button | E9: Floating WhatsApp button | F9: Tap it (if the store has a number). | G9: Opens WhatsApp chat with the store; text readable (dark on green). | J9: =IF(OR(H9="Fail",I9="Fail"),"Fail",IF(OR(H9="Blocked",I9="Blocked"),"Blocked",IF(AND(OR(H9="Pass",H9="N/A"),OR(I9="Pass",I9="N/A"),COUNTIF(H9:I9,"Pass")>0),"Pass",IF(AND(H9="N/A",I9="N/A"),"N/A",IF(COUNTA(H9:I9)=0,"Not run","In progress")))))
A10: STB-07 | B10: P1 | C10: Customer | D10: /c/<category> | E10: Category page | F10: Open a category from the menu. | G10: Only that category's products (and its sub-categories') show; counts right. | J10: =IF(OR(H10="Fail",I10="Fail"),"Fail",IF(OR(H10="Blocked",I10="Blocked"),"Blocked",IF(AND(OR(H10="Pass",H10="N/A"),OR(I10="Pass",I10="N/A"),COUNTIF(H10:I10,"Pass")>0),"Pass",IF(AND(H10="N/A",I10="N/A"),"N/A",IF(COUNTA(H10:I10)=0,"Not run","In progress")))))
A11: STB-08 | B11: P2 | C11: Customer | D11: /c/<category> | E11: Sorting / paging | F11: Use any sort or page controls. | G11: Order changes correctly; page 2 works. | J11: =IF(OR(H11="Fail",I11="Fail"),"Fail",IF(OR(H11="Blocked",I11="Blocked"),"Blocked",IF(AND(OR(H11="Pass",H11="N/A"),OR(I11="Pass",I11="N/A"),COUNTIF(H11:I11,"Pass")>0),"Pass",IF(AND(H11="N/A",I11="N/A"),"N/A",IF(COUNTA(H11:I11)=0,"Not run","In progress")))))
A12: STB-09 | B12: P1 | C12: Customer | D12: /search | E12: Search finds products | F12: Search a product name, a Bangla name and a partial word. | G12: Matching products show. 'No results' message for nonsense. | J12: =IF(OR(H12="Fail",I12="Fail"),"Fail",IF(OR(H12="Blocked",I12="Blocked"),"Blocked",IF(AND(OR(H12="Pass",H12="N/A"),OR(I12="Pass",I12="N/A"),COUNTIF(H12:I12,"Pass")>0),"Pass",IF(AND(H12="N/A",I12="N/A"),"N/A",IF(COUNTA(H12:I12)=0,"Not run","In progress")))))
A13: STB-10 | B13: P2 | C13: Customer | D13: /search | E13: Special characters | F13: Search for %, _, quotes, <script>. | G13: No error, no script runs, no wildcard behaviour. | J13: =IF(OR(H13="Fail",I13="Fail"),"Fail",IF(OR(H13="Blocked",I13="Blocked"),"Blocked",IF(AND(OR(H13="Pass",H13="N/A"),OR(I13="Pass",I13="N/A"),COUNTIF(H13:I13,"Pass")>0),"Pass",IF(AND(H13="N/A",I13="N/A"),"N/A",IF(COUNTA(H13:I13)=0,"Not run","In progress")))))
A14: STB-11 | B14: P1 | C14: Customer | D14: /products/<slug> | E14: Product page content | F14: Open a product. | G14: Title, price, compare-at price, photos, description, size/option picker, trust points show. | J14: =IF(OR(H14="Fail",I14="Fail"),"Fail",IF(OR(H14="Blocked",I14="Blocked"),"Blocked",IF(AND(OR(H14="Pass",H14="N/A"),OR(I14="Pass",I14="N/A"),COUNTIF(H14:I14,"Pass")>0),"Pass",IF(AND(H14="N/A",I14="N/A"),"N/A",IF(COUNTA(H14:I14)=0,"Not run","In progress")))))
A15: STB-12 | B15: P1 | C15: Customer | D15: /products/<slug> | E15: Photo gallery | F15: Swipe/click photos; zoom. | G15: All photos load (AVIF/WebP), keyboard scrollable, no layout jump. | J15: =IF(OR(H15="Fail",I15="Fail"),"Fail",IF(OR(H15="Blocked",I15="Blocked"),"Blocked",IF(AND(OR(H15="Pass",H15="N/A"),OR(I15="Pass",I15="N/A"),COUNTIF(H15:I15,"Pass")>0),"Pass",IF(AND(H15="N/A",I15="N/A"),"N/A",IF(COUNTA(H15:I15)=0,"Not run","In progress")))))
... A35: STB-32 | B35: P3 | C35: Customer | D35: Offline | E35: Offline page | F35: Turn off network; reload a visited page. | G35: Offline page shows, not a browser error. | J35: =IF(OR(H35="Fail",I35="Fail"),"Fail",IF(OR(H35="Blocked",I35="Blocked"),"Blocked",IF(AND(OR(H35="Pass",H35="N/A"),OR(I35="Pass",I35="N/A"),COUNTIF(H35:I35,"Pass")>0),"Pass",IF(AND(H35="N/A",I35="N/A"),"N/A",IF(COUNTA(H35:I35)=0,"Not run","In progress")))))

Sheet 4 Cart & checkout
A1: Storefront: cart, checkout and payment
A2: Mark Phone and Desktop with Pass / Fail / Blocked / N/A. Result fills itself. P1 = release blocker, P2 = should work, P3 = polish.
A3: ID | B3: Priority | C3: Role | D3: Where | E3: Check | F3: Steps | G3: Expected result | H3: Phone 390px | I3: Desktop 1440px | J3: Result | K3: Tester | L3: Date | M3: Bug ref / notes
A4: CHK-01 | B4: P1 | C4: Customer | D4: /cart | E4: Cart shows items | F4: Add 2 products; open /cart. | G4: Lines, variants, quantities, line totals and subtotal right. | J4: =IF(OR(H4="Fail",I4="Fail"),"Fail",IF(OR(H4="Blocked",I4="Blocked"),"Blocked",IF(AND(OR(H4="Pass",H4="N/A"),OR(I4="Pass",I4="N/A"),COUNTIF(H4:I4,"Pass")>0),"Pass",IF(AND(H4="N/A",I4="N/A"),"N/A",IF(COUNTA(H4:I4)=0,"Not run","In progress")))))
A5: CHK-02 | B5: P1 | C5: Customer | D5: /cart | E5: Change quantity / remove | F5: Use +/-; remove an item. | G5: Totals update; empty cart message when none left. | J5: =IF(OR(H5="Fail",I5="Fail"),"Fail",IF(OR(H5="Blocked",I5="Blocked"),"Blocked",IF(AND(OR(H5="Pass",H5="N/A"),OR(I5="Pass",I5="N/A"),COUNTIF(H5:I5,"Pass")>0),"Pass",IF(AND(H5="N/A",I5="N/A"),"N/A",IF(COUNTA(H5:I5)=0,"Not run","In progress")))))
A6: CHK-03 | B6: P1 | C6: Customer | D6: /cart | E6: Cart survives reload | F6: Reload; close and reopen the browser. | G6: Cart is kept (stored in the browser). | J6: =IF(OR(H6="Fail",I6="Fail"),"Fail",IF(OR(H6="Blocked",I6="Blocked"),"Blocked",IF(AND(OR(H6="Pass",H6="N/A"),OR(I6="Pass",I6="N/A"),COUNTIF(H6:I6,"Pass")>0),"Pass",IF(AND(H6="N/A",I6="N/A"),"N/A",IF(COUNTA(H6:I6)=0,"Not run","In progress")))))
A7: CHK-04 | B7: P1 | C7: Customer | D7: /cart | E7: Out-of-stock item in cart | F7: Reduce stock to 0 in admin then open the cart. | G7: Item flagged; checkout blocked for it with a clear message. | J7: =IF(OR(H7="Fail",I7="Fail"),"Fail",IF(OR(H7="Blocked",I7="Blocked"),"Blocked",IF(AND(OR(H7="Pass",H7="N/A"),OR(I7="Pass",I7="N/A"),COUNTIF(H7:I7,"Pass")>0),"Pass",IF(AND(H7="N/A",I7="N/A"),"N/A",IF(COUNTA(H7:I7)=0,"Not run","In progress")))))
A8: CHK-05 | B8: P2 | C8: Customer | D8: /cart | E8: Free delivery progress | F8: Add items under/over the free-delivery amount. | G8: Progress message correct; delivery becomes free over the amount. | J8: =IF(OR(H8="Fail",I8="Fail"),"Fail",IF(OR(H8="Blocked",I8="Blocked"),"Blocked",IF(AND(OR(H8="Pass",H8="N/A"),OR(I8="Pass",I8="N/A"),COUNTIF(H8:I8,"Pass")>0),"Pass",IF(AND(H8="N/A",I8="N/A"),"N/A",IF(COUNTA(H8:I8)=0,"Not run","In progress")))))
A9: CHK-06 | B9: P1 | C9: Customer | D9: /checkout | E9: Checkout page loads | F9: Open /checkout with items. | G9: One page: contact, address, delivery, payment, totals. No console errors. | J9: =IF(OR(H9="Fail",I9="Fail"),"Fail",IF(OR(H9="Blocked",I9="Blocked"),"Blocked",IF(AND(OR(H9="Pass",H9="N/A"),OR(I9="Pass",I9="N/A"),COUNTIF(H9:I9,"Pass")>0),"Pass",IF(AND(H9="N/A",I9="N/A"),"N/A",IF(COUNTA(H9:I9)=0,"Not run","In progress")))))
A10: CHK-07 | B10: P1 | C10: Customer | D10: /checkout | E10: Phone number field | F10: Enter 1712345678, 01712345678, +8801712345678, Bangla digits, and 12345. | G10: Valid forms accepted and formatted; invalid shows error. | J10: =IF(OR(H10="Fail",I10="Fail"),"Fail",IF(OR(H10="Blocked",I10="Blocked"),"Blocked",IF(AND(OR(H10="Pass",H10="N/A"),OR(I10="Pass",I10="N/A"),COUNTIF(H10:I10,"Pass")>0),"Pass",IF(AND(H10="N/A",I10="N/A"),"N/A",IF(COUNTA(H10:I10)=0,"Not run","In progress")))))
A11: CHK-08 | B11: P1 | C11: Customer | D11: /checkout | E11: Address cascade | F11: Pick division > district > upazila. | G11: Lists follow the choice; all 64 districts available; delivery zone and ETA appear. | J11: =IF(OR(H11="Fail",I11="Fail"),"Fail",IF(OR(H11="Blocked",I11="Blocked"),"Blocked",IF(AND(OR(H11="Pass",H11="N/A"),OR(I11="Pass",I11="N/A"),COUNTIF(H11:I11,"Pass")>0),"Pass",IF(AND(H11="N/A",I11="N/A"),"N/A",IF(COUNTA(H11:I11)=0,"Not run","In progress")))))
A12: CHK-09 | B12: P1 | C12: Customer | D12: /checkout | E12: Delivery charge | F12: Choose inside Dhaka, then outside Dhaka. | G12: Charge matches Settings > Delivery charges for each zone. | J12: =IF(OR(H12="Fail",I12="Fail"),"Fail",IF(OR(H12="Blocked",I12="Blocked"),"Blocked",IF(AND(OR(H12="Pass",H12="N/A"),OR(I12="Pass",I12="N/A"),COUNTIF(H12:I12,"Pass")>0),"Pass",IF(AND(H12="N/A",I12="N/A"),"N/A",IF(COUNTA(H12:I12)=0,"Not run","In progress")))))
A13: CHK-10 | B13: P1 | C13: Customer | D13: /checkout | E13: Required field errors | F13: Submit with each required field empty. | G13: Each shows a plain message in the chosen language; first error gets focus. | J13: =IF(OR(H13="Fail",I13="Fail"),"Fail",IF(OR(H13="Blocked",I13="Blocked"),"Blocked",IF(AND(OR(H13="Pass",H13="N/A"),OR(I13="Pass",I13="N/A"),COUNTIF(H13:I13,"Pass")>0),"Pass",IF(AND(H13="N/A",I13="N/A"),"N/A",IF(COUNTA(H13:I13)=0,"Not run","In progress")))))
A14: CHK-11 | B14: P1 | C14: Customer | D14: /checkout | E14: Cash on delivery order | F14: Complete a COD order. | G14: Order placed; success page with order number; total = items + delivery + COD fee (if any). | J14: =IF(OR(H14="Fail",I14="Fail"),"Fail",IF(OR(H14="Blocked",I14="Blocked"),"Blocked",IF(AND(OR(H14="Pass",H14="N/A"),OR(I14="Pass",I14="N/A"),COUNTIF(H14:I14,"Pass")>0),"Pass",IF(AND(H14="N/A",I14="N/A"),"N/A",IF(COUNTA(H14:I14)=0,"Not run","In progress")))))
A15: CHK-12 | B15: P1 | C15: Customer | D15: /checkout | E15: COD fee and limit | F15: Set COD fee and a COD maximum in admin; order above the maximum. | G15: Fee shown; above the maximum COD is refused with advice to pay by bKash/Nagad. | J15: =IF(OR(H15="Fail",I15="Fail"),"Fail",IF(OR(H15="Blocked",I15="Blocked"),"Blocked",IF(AND(OR(H15="Pass",H15="N/A"),OR(I15="Pass",I15="N/A"),COUNTIF(H15:I15,"Pass")>0),"Pass",IF(AND(H15="N/A",I15="N/A"),"N/A",IF(COUNTA(H15:I15)=0,"Not run","In progress")))))
... A39: CHK-36 | B39: P2 | C39: Customer | D39: /draft/<code> | E39: Draft bKash | F39: Place a draft with bKash and a TrxID. | G39: Order waits for payment check like a normal bKash order. | J39: =IF(OR(H39="Fail",I39="Fail"),"Fail",IF(OR(H39="Blocked",I39="Blocked"),"Blocked",IF(AND(OR(H39="Pass",H39="N/A"),OR(I39="Pass",I39="N/A"),COUNTIF(H39:I39,"Pass")>0),"Pass",IF(AND(H39="N/A",I39="N/A"),"N/A",IF(COUNTA(H39:I39)=0,"Not run","In progress")))))

Sheet 5 Customer account
A1: Storefront: account, order tracking, returns, support
A2: Mark Phone and Desktop with Pass / Fail / Blocked / N/A. Result fills itself. P1 = release blocker, P2 = should work, P3 = polish.
A3: ID | B3: Priority | C3: Role | D3: Where | E3: Check | F3: Steps | G3: Expected result | H3: Phone 390px | I3: Desktop 1440px | J3: Result | K3: Tester | L3: Date | M3: Bug ref / notes
A4: CUS-01 | B4: P1 | C4: Customer | D4: /account | E4: Sign in by SMS code | F4: Enter number; receive 6-digit code; enter it. | G4: Signed in; code works once; expires after 5 minutes. | J4: =IF(OR(H4="Fail",I4="Fail"),"Fail",IF(OR(H4="Blocked",I4="Blocked"),"Blocked",IF(AND(OR(H4="Pass",H4="N/A"),OR(I4="Pass",I4="N/A"),COUNTIF(H4:I4,"Pass")>0),"Pass",IF(AND(H4="N/A",I4="N/A"),"N/A",IF(COUNTA(H4:I4)=0,"Not run","In progress")))))
A5: CUS-02 | B5: P1 | C5: Customer | D5: /account | E5: Wrong code limit | F5: Enter wrong codes 5 times. | G5: Code is cancelled; new code needed. | J5: =IF(OR(H5="Fail",I5="Fail"),"Fail",IF(OR(H5="Blocked",I5="Blocked"),"Blocked",IF(AND(OR(H5="Pass",H5="N/A"),OR(I5="Pass",I5="N/A"),COUNTIF(H5:I5,"Pass")>0),"Pass",IF(AND(H5="N/A",I5="N/A"),"N/A",IF(COUNTA(H5:I5)=0,"Not run","In progress")))))
A6: CUS-03 | B6: P1 | C6: Customer | D6: /account | E6: Request limits | F6: Request 4 codes in 15 minutes. | G6: Further requests refused politely. | J6: =IF(OR(H6="Fail",I6="Fail"),"Fail",IF(OR(H6="Blocked",I6="Blocked"),"Blocked",IF(AND(OR(H6="Pass",H6="N/A"),OR(I6="Pass",I6="N/A"),COUNTIF(H6:I6,"Pass")>0),"Pass",IF(AND(H6="N/A",I6="N/A"),"N/A",IF(COUNTA(H6:I6)=0,"Not run","In progress")))))
A7: CUS-04 | B7: P2 | C7: Customer | D7: /account | E7: Order history | F7: Open Account. | G7: Own orders only, newest first, correct status and totals; each links to its order page. | J7: =IF(OR(H7="Fail",I7="Fail"),"Fail",IF(OR(H7="Blocked",I7="Blocked"),"Blocked",IF(AND(OR(H7="Pass",H7="N/A"),OR(I7="Pass",I7="N/A"),COUNTIF(H7:I7,"Pass")>0),"Pass",IF(AND(H7="N/A",I7="N/A"),"N/A",IF(COUNTA(H7:I7)=0,"Not run","In progress")))))
A8: CUS-05 | B8: P2 | C8: Customer | D8: /account | E8: Points and tier | F8: Check points balance, pending points, tier, progress. | G8: Match Admin > Loyalty for that customer. | J8: =IF(OR(H8="Fail",I8="Fail"),"Fail",IF(OR(H8="Blocked",I8="Blocked"),"Blocked",IF(AND(OR(H8="Pass",H8="N/A"),OR(I8="Pass",I8="N/A"),COUNTIF(H8:I8,"Pass")>0),"Pass",IF(AND(H8="N/A",I8="N/A"),"N/A",IF(COUNTA(H8:I8)=0,"Not run","In progress")))))
A9: CUS-06 | B9: P2 | C9: Customer | D9: /account | E9: Birthday | F9: Save birth month/day. | G9: Saved; birthday voucher arrives for Silver+ on the day. | J9: =IF(OR(H9="Fail",I9="Fail"),"Fail",IF(OR(H9="Blocked",I9="Blocked"),"Blocked",IF(AND(OR(H9="Pass",H9="N/A"),OR(I9="Pass",I9="N/A"),COUNTIF(H9:I9,"Pass")>0),"Pass",IF(AND(H9="N/A",I9="N/A"),"N/A",IF(COUNTA(H9:I9)=0,"Not run","In progress")))))
A10: CUS-07 | B10: P2 | C10: Customer | D10: /account | E10: Share referral | F10: Copy/share referral link. | G10: Link works and credits the referrer after the friend's first delivered order. | J10: =IF(OR(H10="Fail",I10="Fail"),"Fail",IF(OR(H10="Blocked",I10="Blocked"),"Blocked",IF(AND(OR(H10="Pass",H10="N/A"),OR(I10="Pass",I10="N/A"),COUNTIF(H10:I10,"Pass")>0),"Pass",IF(AND(H10="N/A",I10="N/A"),"N/A",IF(COUNTA(H10:I10)=0,"Not run","In progress")))))
A11: CUS-08 | B11: P2 | C11: Customer | D11: /account | E11: Sign out | F11: Press sign out. | G11: Signed out; account page asks for sign-in again. | J11: =IF(OR(H11="Fail",I11="Fail"),"Fail",IF(OR(H11="Blocked",I11="Blocked"),"Blocked",IF(AND(OR(H11="Pass",H11="N/A"),OR(I11="Pass",I11="N/A"),COUNTIF(H11:I11,"Pass")>0),"Pass",IF(AND(H11="N/A",I11="N/A"),"N/A",IF(COUNTA(H11:I11)=0,"Not run","In progress")))))
A12: CUS-09 | B12: P1 | C12: Customer | D12: /order/<id> | E12: Track my order | F12: Open the order link after admin moves status. | G12: Timeline shows confirmed, packed, shipped, delivered; courier tracking code/link shown. | J12: =IF(OR(H12="Fail",I12="Fail"),"Fail",IF(OR(H12="Blocked",I12="Blocked"),"Blocked",IF(AND(OR(H12="Pass",H12="N/A"),OR(I12="Pass",I12="N/A"),COUNTIF(H12:I12,"Pass")>0),"Pass",IF(AND(H12="N/A",I12="N/A"),"N/A",IF(COUNTA(H12:I12)=0,"Not run","In progress")))))
A13: CUS-10 | B13: P2 | C13: Customer | D13: /order/<id> | E13: Return or exchange request | F13: On a delivered order, request a return/exchange. | G13: Form asks reason and items; request appears in Admin > Returns. | J13: =IF(OR(H13="Fail",I13="Fail"),"Fail",IF(OR(H13="Blocked",I13="Blocked"),"Blocked",IF(AND(OR(H13="Pass",H13="N/A"),OR(I13="Pass",I13="N/A"),COUNTIF(H13:I13,"Pass")>0),"Pass",IF(AND(H13="N/A",I13="N/A"),"N/A",IF(COUNTA(H13:I13)=0,"Not run","In progress")))))
A14: CUS-11 | B14: P2 | C14: Customer | D14: /order/<id> | E14: Return status tracking | F14: Open the return status link. | G14: Shows stages; refund info once paid back. | J14: =IF(OR(H14="Fail",I14="Fail"),"Fail",IF(OR(H14="Blocked",I14="Blocked"),"Blocked",IF(AND(OR(H14="Pass",H14="N/A"),OR(I14="Pass",I14="N/A"),COUNTIF(H14:I14,"Pass")>0),"Pass",IF(AND(H14="N/A",I14="N/A"),"N/A",IF(COUNTA(H14:I14)=0,"Not run","In progress")))))
A15: CUS-12 | B15: P2 | C15: Customer | D15: Review | E15: Leave a review | F15: Submit a review with rating (and photo if offered). | G15: Shown after moderation or immediately if auto-publish is on; appears in Admin > Reviews. | J15: =IF(OR(H15="Fail",I15="Fail"),"Fail",IF(OR(H15="Blocked",I15="Blocked"),"Blocked",IF(AND(OR(H15="Pass",H15="N/A"),OR(I15="Pass",I15="N/A"),COUNTIF(H15:I15,"Pass")>0),"Pass",IF(AND(H15="N/A",I15="N/A"),"N/A",IF(COUNTA(H15:I15)=0,"Not run","In progress")))))
... A21: CUS-18 | B21: P2 | C21: Customer | D21: Privacy | E21: Data shown | F21: Check every customer-facing page. | G21: No other customer's data, no staff notes, no internal fields. | J21: =IF(OR(H21="Fail",I21="Fail"),"Fail",IF(OR(H21="Blocked",I21="Blocked"),"Blocked",IF(AND(OR(H21="Pass",H21="N/A"),OR(I21="Pass",I21="N/A"),COUNTIF(H21:I21,"Pass")>0),"Pass",IF(AND(H21="N/A",I21="N/A"),"N/A",IF(COUNTA(H21:I21)=0,"Not run","In progress")))))

Sheet 6 Admin access
A1: Admin: sign-in, dashboard and navigation
A2: Mark Phone and Desktop with Pass / Fail / Blocked / N/A. Result fills itself. P1 = release blocker, P2 = should work, P3 = polish.
A3: ID | B3: Priority | C3: Role | D3: Where | E3: Check | F3: Steps | G3: Expected result | H3: Phone 390px | I3: Desktop 1440px | J3: Result | K3: Tester | L3: Date | M3: Bug ref / notes
A4: ADM-01 | B4: P1 | C4: Any | D4: Sign-in | E4: Sign in with email and password | F4: Open the admin address; sign in with a valid account. | G4: Lands on Home. Wrong password gives a plain error, no hint which part was wrong. | J4: =IF(OR(H4="Fail",I4="Fail"),"Fail",IF(OR(H4="Blocked",I4="Blocked"),"Blocked",IF(AND(OR(H4="Pass",H4="N/A"),OR(I4="Pass",I4="N/A"),COUNTIF(H4:I4,"Pass")>0),"Pass",IF(AND(H4="N/A",I4="N/A"),"N/A",IF(COUNTA(H4:I4)=0,"Not run","In progress")))))
A5: ADM-02 | B5: P1 | C5: Team member | D5: Sign-in | E5: First-time / forgot password | F5: Use 'First time here, or forgot your password?'; get the code by email; set a password. | G5: Code arrives within a minute; password rules enforced (10+ characters); can sign in after. | J5: =IF(OR(H5="Fail",I5="Fail"),"Fail",IF(OR(H5="Blocked",I5="Blocked"),"Blocked",IF(AND(OR(H5="Pass",H5="N/A"),OR(I5="Pass",I5="N/A"),COUNTIF(H5:I5,"Pass")>0),"Pass",IF(AND(H5="N/A",I5="N/A"),"N/A",IF(COUNTA(H5:I5)=0,"Not run","In progress")))))
A6: ADM-03 | B6: P1 | C6: Team member | D6: Sign-in | E6: Two-factor sign-in | F6: Turn on two-factor in Security; sign out; sign in again. | G6: Asks for the authenticator code; wrong code refused; right code signs in. | J6: =IF(OR(H6="Fail",I6="Fail"),"Fail",IF(OR(H6="Blocked",I6="Blocked"),"Blocked",IF(AND(OR(H6="Pass",H6="N/A"),OR(I6="Pass",I6="N/A"),COUNTIF(H6:I6,"Pass")>0),"Pass",IF(AND(H6="N/A",I6="N/A"),"N/A",IF(COUNTA(H6:I6)=0,"Not run","In progress")))))
A7: ADM-04 | B7: P1 | C7: Team member | D7: Sign-in | E7: Session end | F7: Sign out; press Back. | G7: Cannot see admin pages; redirected to sign-in. | J7: =IF(OR(H7="Fail",I7="Fail"),"Fail",IF(OR(H7="Blocked",I7="Blocked"),"Blocked",IF(AND(OR(H7="Pass",H7="N/A"),OR(I7="Pass",I7="N/A"),COUNTIF(H7:I7,"Pass")>0),"Pass",IF(AND(H7="N/A",I7="N/A"),"N/A",IF(COUNTA(H7:I7)=0,"Not run","In progress")))))
A8: ADM-05 | B8: P1 | C8: Team member | D8: Sign-in | E8: Pages need sign-in | F8: Open /orders, /products, /pos in a private window. | G8: All redirect to sign-in. No data visible. | J8: =IF(OR(H8="Fail",I8="Fail"),"Fail",IF(OR(H8="Blocked",I8="Blocked"),"Blocked",IF(AND(OR(H8="Pass",H8="N/A"),OR(I8="Pass",I8="N/A"),COUNTIF(H8:I8,"Pass")>0),"Pass",IF(AND(H8="N/A",I8="N/A"),"N/A",IF(COUNTA(H8:I8)=0,"Not run","In progress")))))
A9: ADM-06 | B9: P1 | C9: Team member | D9: /join/<token> | E9: Invite acceptance | F9: Invite a new person; open their link; set name and password. | G9: Joined with the invited role; link cannot be used twice or after expiry. | J9: =IF(OR(H9="Fail",I9="Fail"),"Fail",IF(OR(H9="Blocked",I9="Blocked"),"Blocked",IF(AND(OR(H9="Pass",H9="N/A"),OR(I9="Pass",I9="N/A"),COUNTIF(H9:I9,"Pass")>0),"Pass",IF(AND(H9="N/A",I9="N/A"),"N/A",IF(COUNTA(H9:I9)=0,"Not run","In progress")))))
A10: ADM-07 | B10: P2 | C10: Team member | D10: /choose-store | E10: Several stores | F10: Sign in with an account on two stores. | G10: Choose-store page; each opens its own store only. | J10: =IF(OR(H10="Fail",I10="Fail"),"Fail",IF(OR(H10="Blocked",I10="Blocked"),"Blocked",IF(AND(OR(H10="Pass",H10="N/A"),OR(I10="Pass",I10="N/A"),COUNTIF(H10:I10,"Pass")>0),"Pass",IF(AND(H10="N/A",I10="N/A"),"N/A",IF(COUNTA(H10:I10)=0,"Not run","In progress")))))
A11: ADM-08 | B11: P1 | C11: Store owner | D11: Plan | E11: Locked store | F11: Let a trial expire / suspend a store in Platform admin. | G11: Admin shows 'See plans and pay'; no order or product work possible. | J11: =IF(OR(H11="Fail",I11="Fail"),"Fail",IF(OR(H11="Blocked",I11="Blocked"),"Blocked",IF(AND(OR(H11="Pass",H11="N/A"),OR(I11="Pass",I11="N/A"),COUNTIF(H11:I11,"Pass")>0),"Pass",IF(AND(H11="N/A",I11="N/A"),"N/A",IF(COUNTA(H11:I11)=0,"Not run","In progress")))))
A12: ADM-09 | B12: P1 | C12: Store owner | D12: / | E12: Dashboard numbers | F12: Compare sales today, orders today, to pack, payments to check with the Orders list. | G12: Numbers match the lists. Date ranges (today/7/30) change them correctly (Dhaka time). | J12: =IF(OR(H12="Fail",I12="Fail"),"Fail",IF(OR(H12="Blocked",I12="Blocked"),"Blocked",IF(AND(OR(H12="Pass",H12="N/A"),OR(I12="Pass",I12="N/A"),COUNTIF(H12:I12,"Pass")>0),"Pass",IF(AND(H12="N/A",I12="N/A"),"N/A",IF(COUNTA(H12:I12)=0,"Not run","In progress")))))
A13: ADM-10 | B13: P2 | C13: Store owner | D13: / | E13: Dashboard shortcuts | F13: Press each card/link on the dashboard. | G13: Each opens the right filtered page. | J13: =IF(OR(H13="Fail",I13="Fail"),"Fail",IF(OR(H13="Blocked",I13="Blocked"),"Blocked",IF(AND(OR(H13="Pass",H13="N/A"),OR(I13="Pass",I13="N/A"),COUNTIF(H13:I13,"Pass")>0),"Pass",IF(AND(H13="N/A",I13="N/A"),"N/A",IF(COUNTA(H13:I13)=0,"Not run","In progress")))))
A14: ADM-11 | B14: P2 | C14: Store owner | D14: / | E14: Setup checklist | F14: New store: follow 'Finish setting up'. | G14: Items tick off as done; links open the right screens. | J14: =IF(OR(H14="Fail",I14="Fail"),"Fail",IF(OR(H14="Blocked",I14="Blocked"),"Blocked",IF(AND(OR(H14="Pass",H14="N/A"),OR(I14="Pass",I14="N/A"),COUNTIF(H14:I14,"Pass")>0),"Pass",IF(AND(H14="N/A",I14="N/A"),"N/A",IF(COUNTA(H14:I14)=0,"Not run","In progress")))))
A15: ADM-12 | B15: P2 | C15: Any | D15: Top bar | E15: Search | F15: Use the top-bar search for an order number, customer, product. | G15: Results list; each result opens the right record. | J15: =IF(OR(H15="Fail",I15="Fail"),"Fail",IF(OR(H15="Blocked",I15="Blocked"),"Blocked",IF(AND(OR(H15="Pass",H15="N/A"),OR(I15="Pass",I15="N/A"),COUNTIF(H15:I15,"Pass")>0),"Pass",IF(AND(H15="N/A",I15="N/A"),"N/A",IF(COUNTA(H15:I15)=0,"Not run","In progress")))))
... A22: ADM-19 | B22: P2 | C22: Any | D22: /ui-kit | E22: Internal pages hidden | F22: Try /ui-kit on production. | G22: Not reachable by customers; only for team if kept. | J22: =IF(OR(H22="Fail",I22="Fail"),"Fail",IF(OR(H22="Blocked",I22="Blocked"),"Blocked",IF(AND(OR(H22="Pass",H22="N/A"),OR(I22="Pass",I22="N/A"),COUNTIF(H22:I22,"Pass")>0),"Pass",IF(AND(H22="N/A",I22="N/A"),"N/A",IF(COUNTA(H22:I22)=0,"Not run","In progress")))))

Sheet 7 Admin orders
A1: Admin: orders, shipping, printing, returns, fraud
A2: Mark Phone and Desktop with Pass / Fail / Blocked / N/A. Result fills itself. P1 = release blocker, P2 = should work, P3 = polish.
A3: ID | B3: Priority | C3: Role | D3: Where | E3: Check | F3: Steps | G3: Expected result | H3: Phone 390px | I3: Desktop 1440px | J3: Result | K3: Tester | L3: Date | M3: Bug ref / notes
A4: ORD-01 | B4: P1 | C4: Owner | D4: /orders | E4: Orders list and tabs | F4: Open Orders; click each tab (All, New, Check payment, High risk, To pack, Shipped, Delivered, Returns, Cancelled). | G4: Counts match lists; each tab shows the right statuses only. | J4: =IF(OR(H4="Fail",I4="Fail"),"Fail",IF(OR(H4="Blocked",I4="Blocked"),"Blocked",IF(AND(OR(H4="Pass",H4="N/A"),OR(I4="Pass",I4="N/A"),COUNTIF(H4:I4,"Pass")>0),"Pass",IF(AND(H4="N/A",I4="N/A"),"N/A",IF(COUNTA(H4:I4)=0,"Not run","In progress")))))
A5: ORD-02 | B5: P1 | C5: Owner | D5: /orders | E5: Search | F5: Search order number, customer name, last 4+ digits of phone. | G5: Finds the right order; % and _ act as normal characters. | J5: =IF(OR(H5="Fail",I5="Fail"),"Fail",IF(OR(H5="Blocked",I5="Blocked"),"Blocked",IF(AND(OR(H5="Pass",H5="N/A"),OR(I5="Pass",I5="N/A"),COUNTIF(H5:I5,"Pass")>0),"Pass",IF(AND(H5="N/A",I5="N/A"),"N/A",IF(COUNTA(H5:I5)=0,"Not run","In progress")))))
A6: ORD-03 | B6: P2 | C6: Owner | D6: /orders | E6: Filters | F6: Use payment, courier, date, district, label filters; combine them. | G6: Results narrow correctly; clearing restores all; filters survive paging. | J6: =IF(OR(H6="Fail",I6="Fail"),"Fail",IF(OR(H6="Blocked",I6="Blocked"),"Blocked",IF(AND(OR(H6="Pass",H6="N/A"),OR(I6="Pass",I6="N/A"),COUNTIF(H6:I6,"Pass")>0),"Pass",IF(AND(H6="N/A",I6="N/A"),"N/A",IF(COUNTA(H6:I6)=0,"Not run","In progress")))))
A7: ORD-04 | B7: P2 | C7: Owner | D7: /orders | E7: Paging | F7: With more than 25 orders go to page 2. | G7: Right orders, count text correct, filters kept. | J7: =IF(OR(H7="Fail",I7="Fail"),"Fail",IF(OR(H7="Blocked",I7="Blocked"),"Blocked",IF(AND(OR(H7="Pass",H7="N/A"),OR(I7="Pass",I7="N/A"),COUNTIF(H7:I7,"Pass")>0),"Pass",IF(AND(H7="N/A",I7="N/A"),"N/A",IF(COUNTA(H7:I7)=0,"Not run","In progress")))))
A8: ORD-05 | B8: P2 | C8: Owner | D8: /orders | E8: Quick view | F8: Press Quick view on a row. | G8: Drawer shows items, customer, payment; closes cleanly. | J8: =IF(OR(H8="Fail",I8="Fail"),"Fail",IF(OR(H8="Blocked",I8="Blocked"),"Blocked",IF(AND(OR(H8="Pass",H8="N/A"),OR(I8="Pass",I8="N/A"),COUNTIF(H8:I8,"Pass")>0),"Pass",IF(AND(H8="N/A",I8="N/A"),"N/A",IF(COUNTA(H8:I8)=0,"Not run","In progress")))))
A9: ORD-06 | B9: P1 | C9: Owner | D9: /orders | E9: Bulk mark as packed | F9: Select 3 confirmed orders; Mark selected as packed. | G9: All move to 'being packed'; message says how many; non-confirmed ones skipped and counted. | J9: =IF(OR(H9="Fail",I9="Fail"),"Fail",IF(OR(H9="Blocked",I9="Blocked"),"Blocked",IF(AND(OR(H9="Pass",H9="N/A"),OR(I9="Pass",I9="N/A"),COUNTIF(H9:I9,"Pass")>0),"Pass",IF(AND(H9="N/A",I9="N/A"),"N/A",IF(COUNTA(H9:I9)=0,"Not run","In progress")))))
A10: ORD-07 | B10: P1 | C10: Owner | D10: /orders | E10: Bulk confirm | F10: Select new orders; Confirm selected. | G10: Confirmed; message '2 confirmed'; skipped ones explained. | J10: =IF(OR(H10="Fail",I10="Fail"),"Fail",IF(OR(H10="Blocked",I10="Blocked"),"Blocked",IF(AND(OR(H10="Pass",H10="N/A"),OR(I10="Pass",I10="N/A"),COUNTIF(H10:I10,"Pass")>0),"Pass",IF(AND(H10="N/A",I10="N/A"),"N/A",IF(COUNTA(H10:I10)=0,"Not run","In progress")))))
A11: ORD-08 | B11: P1 | C11: Owner | D11: /orders | E11: Bulk cancel needs a reason | F11: Select orders; Cancel selected without a reason, then with one. | G11: Without: refused. With: cancelled, stock returns, reason on each timeline. | J11: =IF(OR(H11="Fail",I11="Fail"),"Fail",IF(OR(H11="Blocked",I11="Blocked"),"Blocked",IF(AND(OR(H11="Pass",H11="N/A"),OR(I11="Pass",I11="N/A"),COUNTIF(H11:I11,"Pass")>0),"Pass",IF(AND(H11="N/A",I11="N/A"),"N/A",IF(COUNTA(H11:I11)=0,"Not run","In progress")))))
A12: ORD-09 | B12: P1 | C12: Owner | D12: /orders | E12: Bulk book courier | F12: Select to-pack orders; choose courier; Book courier for selected. | G12: Booked with tracking; failures reported with reason. | J12: =IF(OR(H12="Fail",I12="Fail"),"Fail",IF(OR(H12="Blocked",I12="Blocked"),"Blocked",IF(AND(OR(H12="Pass",H12="N/A"),OR(I12="Pass",I12="N/A"),COUNTIF(H12:I12,"Pass")>0),"Pass",IF(AND(H12="N/A",I12="N/A"),"N/A",IF(COUNTA(H12:I12)=0,"Not run","In progress")))))
A13: ORD-10 | B13: P2 | C13: Owner | D13: /orders | E13: Bulk print | F13: Print packing slips / invoices for selected. | G13: New tab with all selected documents; print preview paginates one per page. | J13: =IF(OR(H13="Fail",I13="Fail"),"Fail",IF(OR(H13="Blocked",I13="Blocked"),"Blocked",IF(AND(OR(H13="Pass",H13="N/A"),OR(I13="Pass",I13="N/A"),COUNTIF(H13:I13,"Pass")>0),"Pass",IF(AND(H13="N/A",I13="N/A"),"N/A",IF(COUNTA(H13:I13)=0,"Not run","In progress")))))
