Workbook

Sheet Summary
A1: BizTrackBD: 6- and 12-month returns (base case)
A2: Everything here is calculated. Change inputs on the other tabs. Profit is before salaries unless entered on Inputs (cell B14).
A4: Metric | B4: First 6 months (Nov-Apr) | C4: Full 12 months (Nov-Oct) | D4: What it means
A5: Spend
A6: Total marketing spend | B6: =SUM(Forecast!B31:G31) -> 514334.72 | C6: =SUM(Forecast!B31:M31) -> 1382699.5 | D6: Ads, content, creators, events, discounts, commissions
A7: of which Meta ads | B7: =SUM('Marketing Budget'!B19:G19) -> 196000 | C7: ='Marketing Budget'!N19 -> 595000 | D7: Prospecting + retargeting
A8: of which Google ads | B8: =SUM('Marketing Budget'!B20:G20) -> 84000 | C8: ='Marketing Budget'!N20 -> 255000 | D8: Search + YouTube
A9: Platform and running costs | B9: =SUM(Forecast!B28:G28)+SUM(Forecast!B29:G29)+SUM(Forecast!B30:G30) -> 89009.165 | C9: =SUM(Forecast!B28:M28)+SUM(Forecast!B29:M29)+SUM(Forecast!B30:M30) -> 343727.68 | D9: Hosting, SMS, email, bKash charges, admin
A10: Total expenses | B10: =B6+B9 -> 603343.88 | C10: =C6+C9 -> 1726427.2 | D10: Everything you pay out
A11: Ad performance
A12: Impressions | B12: =SUM(Forecast!B7:G7) -> 757333.33 | C12: =SUM(Forecast!B7:M7) -> 2299047.6 | D12: Times your ads are shown
A13: Clicks | B13: =SUM(Forecast!B8:G8) -> 14906.667 | C13: =SUM(Forecast!B8:M8) -> 45252.381
A14: Blended CPM | B14: =IFERROR(SUM(Forecast!B6:G6)/B12*1000,0) -> 369.71831 | C14: =IFERROR(SUM(Forecast!B6:M6)/C12*1000,0) -> 369.71831 | D14: Cost per 1,000 views, all channels
A15: Blended CPC | B15: =IFERROR(SUM(Forecast!B6:G6)/B13,0) -> 18.783542 | C15: =IFERROR(SUM(Forecast!B6:M6)/C13,0) -> 18.783542 | D15: Cost per click, all channels
A16: Blended CTR | B16: =IFERROR(B13/B12,0) -> 0.019683099 | C16: =IFERROR(C13/C12,0) -> 0.019683099 | D16: Share of viewers who click
A17: Trial sign-ups (all sources) | B17: =SUM(Forecast!B17:G17) -> 999.2 | C17: =SUM(Forecast!B17:M17) -> 3025.0714
A18: Cost per trial from ads (CPL) | B18: =IFERROR(SUM(Forecast!B6:G6)/SUM(Forecast!B13:G15),0) -> 364.01456 | C18: =IFERROR(SUM(Forecast!B6:M6)/SUM(Forecast!B13:M15),0) -> 364.01456 | D18: Arafat Labs B2B/SaaS range: ৳400-1,200
A19: Growth
A20: New paying stores won | B20: =SUM(Forecast!B20:G20)+SUM(Forecast!B21:G21) -> 142.25571 | C20: =SUM(Forecast!B20:M20)+SUM(Forecast!B21:M21) -> 470.21214
A21: Paying stores at the end | B21: =Forecast!G24 -> 134.25446 | C21: =Forecast!M24 -> 405.89709 | D21: After 4% monthly churn
A22: MRR at the end | B22: =Forecast!G26 -> 163656.19 | C22: =Forecast!M26 -> 494788.55 | D22: Monthly recurring revenue
A23: Annual run rate (MRR × 12) | B23: =B22*12 -> 1963874.2 | C23: =C22*12 -> 5937462.6 | D23: What a year looks like at the end-of-period pace
A24: Returns
A25: Total revenue | B25: =SUM(Forecast!B25:G25) -> 407494.4 | C25: =SUM(Forecast!B25:M25) -> 2454789.8
A26: Profit or loss for the period | B26: =B25-B10 -> -195849.48 | C26: =C25-C10 -> 728362.61 | D26: Revenue minus all expenses
A27: Lowest cash point (money you must fund) | B27: =-MIN(Forecast!B35:G35) -> 230845.4 | C27: =-MIN(Forecast!B35:M35) -> 230845.4 | D27: Peak investment needed before profits repay it
A28: Marketing ROI | B28: =IFERROR(B26/B6,0) -> -0.38078216 | C28: =IFERROR(C26/C6,0) -> 0.52676855 | D28: Profit ÷ marketing spent. Negative early is normal for SaaS
A29: ROAS, first paid month | B29: =IFERROR(SUMPRODUCT(Forecast!B13:G13*'Ad Benchmarks'!$B$10+Forecast!B14:G14*'Ad Benchmarks'!$C$10+Forecast!B15:G15*'Ad Benchmarks'!$D$10)*Inputs!$B$22/SUM(Forecast!B6:G6),0) -> 0.53888507 | C29: =Forecast!N39 -> 0.53888507 | D29: One month of revenue ÷ ad cost to win it
A30: ROAS, 12-month value | B30: =IFERROR(SUMPRODUCT(Forecast!B13:G13*'Ad Benchmarks'!$B$10+Forecast!B14:G14*'Ad Benchmarks'!$C$10+Forecast!B15:G15*'Ad Benchmarks'!$D$10)*'Ad Benchmarks'!$B$20/SUM(Forecast!B6:G6),0) -> 5.2176233 | C30: =Forecast!N40 -> 5.2176233 | D30: Year-one revenue from ad-won stores ÷ ad spend. Aim for 3x+
A31: CAC from ads | B31: =IFERROR(SUM(Forecast!B6:G6)/SUMPRODUCT(Forecast!B13:G13*'Ad Benchmarks'!$B$10+Forecast!B14:G14*'Ad Benchmarks'!$C$10+Forecast!B15:G15*'Ad Benchmarks'!$D$10),0) -> 2262.0779 | C31: =Forecast!N37 -> 2262.0779 | D31: Target: under ৳5,000
A32: CAC all-in | B32: =IFERROR(B6/(SUMPRODUCT(Forecast!B13:G13*'Ad Benchmarks'!$B$10+Forecast!B14:G14*'Ad Benchmarks'!$C$10+Forecast!B15:G15*'Ad Benchmarks'!$D$10)+SUM(Forecast!B16:G16)*'Ad Benchmarks'!$B$17),0) -> 2837.2392 | C32: =Forecast!N38 -> 2521.9744 | D32: All marketing ÷ all stores won
A33: LTV : CAC (all-in) | B33: =IFERROR('Ad Benchmarks'!$B$21/B32,0) -> 9.6556408 | C33: =IFERROR('Ad Benchmarks'!$B$21/C32,0) -> 10.862665 | D33: Healthy SaaS is 3x or more
A34: Months to earn back CAC | B34: =IFERROR(B32/'Ad Benchmarks'!$B$22,0) -> 2.5891601 | C34: =IFERROR(C32/'Ad Benchmarks'!$B$22,0) -> 2.3014611 | D34: Target: under 6 months
A35: First profitable month | B35: =IFERROR(INDEX(Forecast!B4:G4,MATCH(1,Forecast!B44:G44,0)),"Not yet") -> Mar 2027 | C35: =IFERROR(INDEX(Forecast!B4:M4,MATCH(1,Forecast!B44:M44,0)),"Not within 12 months") -> Mar 2027 | D35: Revenue beats all costs that month
A36: Month all money is earned back | B36: =IFERROR(INDEX(Forecast!B4:G4,MATCH(1,Forecast!B45:G45,0)),"Not yet") -> Not yet | C36: =IFERROR(INDEX(Forecast!B4:M4,MATCH(1,Forecast!B45:M45,0)),"Not within 12 months") -> Jul 2027 | D36: Cumulative cash back to zero

Sheet Inputs
A1: BizTrackBD cost model: inputs
A2: Blue = an input you can change. Yellow = a guess to replace with real data. Black = calculated. Change only blue cells.
A3: Item | B3: Value | C3: Unit | E3: Source / note
A4: General
A5: Exchange rate | B5: 129 | C5: ৳ per US$ | E5: You, 14 Oct 2026 (your card rate incl. bank charges)
A6: bKash cash-out charge on subscription money | B6: 0.0145 | C6: % of revenue | E6: You, 14 Oct 2026
A8: Fixed monthly costs
A9: Vercel Pro seats | B9: 1 | C9: seats | E9: You, 14 Oct 2026
A10: Vercel Pro price per seat | B10: 20 | C10: US$ / month | E10: You; Vercel Pro is US$20 per seat (MakerKit, May 2026)
A11: Supabase Pro plan | B11: 25 | C11: US$ / month | E11: You; includes US$10 compute credit (Focus Reactive, Oct 2026)
A12: Domains (biztrack.bd + biztrackbd.com) | B12: 2000 | C12: ৳ / year | E12: You, 14 Oct 2026
A13: Business admin (licence, accounting, misc.) | B13: 2000 | C13: ৳ / month | E13: Your answer '2000' to question 8; read as ৳2,000 a month. Change if it is yearly or meant for AI
A14: Team salaries for BizTrack | B14: 0 | C14: ৳ / month | E14: Not given. Enter support, developer and marketing time here; it will be your biggest cost
A15: Other paid tools | B15: 0 | C15: ৳ / month | E15: You: none for now
A17: Plans
A18: Plan | B18: Price (৳ / month) | C18: Share of stores | D18: SMS sent per store / month | E18: Source / note
A19: Starter | B19: 699 | C19: 0.6 | D19: 60 | E19: Prices from the live pricing page. Share and SMS use are guesses until real data
A20: Pro | B20: 1499 | C20: 0.3 | D20: 150
A21: Business | B21: 3499 | C21: 0.1 | D21: 400
A22: Blended (weighted average) | B22: =SUMPRODUCT(B19:B21,C19:C21) -> 1219 | C22: =SUM(C19:C21) -> 1 | D22: =SUMPRODUCT(C19:C21,D19:D21) -> 121 | E22: Share of stores must add up to 100%
A24: SMS (shared platform account)
A25: Price per SMS | B25: 0.8 | C25: ৳ per SMS part | E25: You, 14 Oct 2026
A26: SMS parts per message (Bangla averages more) | B26: 1.5 | C26: parts | E26: A Bangla SMS holds about 70 characters, so longer messages bill as 2-3 parts. Guess
A27: Share of stores using their own SMS account | B27: 0.3 | C27: % of stores | E27: You: both options. These stores cost you nothing for SMS. Guess
A29: Email (recommended: Amazon SES)
A30: Emails per store per month | B30: 300 | C30: emails | E30: Sign-in codes, order and staff emails. Guess
A31: Amazon SES price per 1,000 emails | B31: 0.1 | C31: US$ | E31: À la carte rate (CarlyEmail, checked against AWS on 2 Oct 2026)
A33: Hosting usage (overage beyond plan allowances)
A34: Image storage per store | B34: 0.5 | C34: GB | E34: Guess. Check Supabase usage after month 1
A35: Supabase storage included | B35: 100 | C35: GB | E35: Supabase Pro (Focus Reactive, Oct 2026)
A36: Supabase storage overage | B36: 0.021 | C36: US$ per GB | E36: Focus Reactive, Oct 2026
A37: Database size per store | B37: 0.02 | C37: GB | E37: Guess (about 20 MB)
A38: Supabase database included | B38: 8 | C38: GB | E38: Supabase Pro (Focus Reactive, Oct 2026)
A39: Supabase database overage | B39: 0.125 | C39: US$ per GB | E39: Supabase disk rate, check pricing page
A40: Vercel usage per store | B40: 0.05 | C40: US$ / month | E40: Guess: functions, CPU, images. Check Vercel usage page after month 1
A41: Vercel usage credit per seat | B41: 20 | C41: US$ / month | E41: Vercel Pro includes US$20 usage credit per seat (MakerKit, May 2026)
A42: Supabase: stores before upgrading to Small compute | B42: 200 | C42: stores | E42: Guess
A43: Small compute extra cost | B43: 5 | C43: US$ / month | E43: Small minus the US$10 credit. Check pricing page
A44: Supabase: stores before upgrading to Medium compute | B44: 600 | C44: stores | E44: Guess
A45: Medium compute extra cost | B45: 50 | C45: US$ / month | E45: Medium minus the US$10 credit. Check pricing page
...

Sheet Cost Model
A1: Monthly profit and loss by number of paying stores (৳)
A2: Change store counts in row 4 (blue). Everything else is calculated from the Inputs tab.
A4: Paying stores | B4: 20 | C4: 100 | D4: 250 | E4: 500 | F4: 1000
A5: Revenue
A6: Subscription revenue | B6: =B$4*Inputs!$B$22 -> 24380 | C6: =C$4*Inputs!$B$22 -> 121900 | D6: =D$4*Inputs!$B$22 -> 304750 | E6: =E$4*Inputs!$B$22 -> 609500 | F6: =F$4*Inputs!$B$22 -> 1219000
A7: bKash cash-out charge | B7: =B6*Inputs!$B$6 -> 353.51 | C7: =C6*Inputs!$B$6 -> 1767.55 | D7: =D6*Inputs!$B$6 -> 4418.875 | E7: =E6*Inputs!$B$6 -> 8837.75 | F7: =F6*Inputs!$B$6 -> 17675.5
A8: Net revenue | B8: =B6-B7 -> 24026.49 | C8: =C6-C7 -> 120132.45 | D8: =D6-D7 -> 300331.12 | E8: =E6-E7 -> 600662.25 | F8: =F6-F7 -> 1201324.5
A10: Fixed costs
A11: Vercel Pro | B11: =Inputs!$B$9*Inputs!$B$10*Inputs!$B$5 -> 2580 | C11: =Inputs!$B$9*Inputs!$B$10*Inputs!$B$5 -> 2580 | D11: =Inputs!$B$9*Inputs!$B$10*Inputs!$B$5 -> 2580 | E11: =Inputs!$B$9*Inputs!$B$10*Inputs!$B$5 -> 2580 | F11: =Inputs!$B$9*Inputs!$B$10*Inputs!$B$5 -> 2580
A12: Supabase Pro | B12: =Inputs!$B$11*Inputs!$B$5 -> 3225 | C12: =Inputs!$B$11*Inputs!$B$5 -> 3225 | D12: =Inputs!$B$11*Inputs!$B$5 -> 3225 | E12: =Inputs!$B$11*Inputs!$B$5 -> 3225 | F12: =Inputs!$B$11*Inputs!$B$5 -> 3225
A13: Domains (yearly ÷ 12) | B13: =Inputs!$B$12/12 -> 166.66667 | C13: =Inputs!$B$12/12 -> 166.66667 | D13: =Inputs!$B$12/12 -> 166.66667 | E13: =Inputs!$B$12/12 -> 166.66667 | F13: =Inputs!$B$12/12 -> 166.66667
A14: Business admin | B14: =Inputs!$B$13 -> 2000 | C14: =Inputs!$B$13 -> 2000 | D14: =Inputs!$B$13 -> 2000 | E14: =Inputs!$B$13 -> 2000 | F14: =Inputs!$B$13 -> 2000
A15: Team salaries | B15: =Inputs!$B$14 -> 0 | C15: =Inputs!$B$14 -> 0 | D15: =Inputs!$B$14 -> 0 | E15: =Inputs!$B$14 -> 0 | F15: =Inputs!$B$14 -> 0
A16: Other paid tools | B16: =Inputs!$B$15 -> 0 | C16: =Inputs!$B$15 -> 0 | D16: =Inputs!$B$15 -> 0 | E16: =Inputs!$B$15 -> 0 | F16: =Inputs!$B$15 -> 0
A17: Total fixed costs | B17: =SUM(B11:B16) -> 7971.6667 | C17: =SUM(C11:C16) -> 7971.6667 | D17: =SUM(D11:D16) -> 7971.6667 | E17: =SUM(E11:E16) -> 7971.6667 | F17: =SUM(F11:F16) -> 7971.6667
A19: Variable costs (grow with stores)
A20: SMS (shared account) | B20: =B$4*(1-Inputs!$B$27)*Inputs!$D$22*Inputs!$B$26*Inputs!$B$25 -> 2032.8 | C20: =C$4*(1-Inputs!$B$27)*Inputs!$D$22*Inputs!$B$26*Inputs!$B$25 -> 10164 | D20: =D$4*(1-Inputs!$B$27)*Inputs!$D$22*Inputs!$B$26*Inputs!$B$25 -> 25410 | E20: =E$4*(1-Inputs!$B$27)*Inputs!$D$22*Inputs!$B$26*Inputs!$B$25 -> 50820 | F20: =F$4*(1-Inputs!$B$27)*Inputs!$D$22*Inputs!$B$26*Inputs!$B$25 -> 101640
A21: Email (Amazon SES) | B21: =B$4*Inputs!$B$30/1000*Inputs!$B$31*Inputs!$B$5 -> 77.4 | C21: =C$4*Inputs!$B$30/1000*Inputs!$B$31*Inputs!$B$5 -> 387 | D21: =D$4*Inputs!$B$30/1000*Inputs!$B$31*Inputs!$B$5 -> 967.5 | E21: =E$4*Inputs!$B$30/1000*Inputs!$B$31*Inputs!$B$5 -> 1935 | F21: =F$4*Inputs!$B$30/1000*Inputs!$B$31*Inputs!$B$5 -> 3870
A22: Supabase storage overage | B22: =MAX(0,B$4*Inputs!$B$34-Inputs!$B$35)*Inputs!$B$36*Inputs!$B$5 -> 0 | C22: =MAX(0,C$4*Inputs!$B$34-Inputs!$B$35)*Inputs!$B$36*Inputs!$B$5 -> 0 | D22: =MAX(0,D$4*Inputs!$B$34-Inputs!$B$35)*Inputs!$B$36*Inputs!$B$5 -> 67.725 | E22: =MAX(0,E$4*Inputs!$B$34-Inputs!$B$35)*Inputs!$B$36*Inputs!$B$5 -> 406.35 | F22: =MAX(0,F$4*Inputs!$B$34-Inputs!$B$35)*Inputs!$B$36*Inputs!$B$5 -> 1083.6
A23: Supabase database overage | B23: =MAX(0,B$4*Inputs!$B$37-Inputs!$B$38)*Inputs!$B$39*Inputs!$B$5 -> 0 | C23: =MAX(0,C$4*Inputs!$B$37-Inputs!$B$38)*Inputs!$B$39*Inputs!$B$5 -> 0 | D23: =MAX(0,D$4*Inputs!$B$37-Inputs!$B$38)*Inputs!$B$39*Inputs!$B$5 -> 0 | E23: =MAX(0,E$4*Inputs!$B$37-Inputs!$B$38)*Inputs!$B$39*Inputs!$B$5 -> 32.25 | F23: =MAX(0,F$4*Inputs!$B$37-Inputs!$B$38)*Inputs!$B$39*Inputs!$B$5 -> 193.5
A24: Vercel usage beyond credit | B24: =MAX(0,B$4*Inputs!$B$40-Inputs!$B$9*Inputs!$B$41)*Inputs!$B$5 -> 0 | C24: =MAX(0,C$4*Inputs!$B$40-Inputs!$B$9*Inputs!$B$41)*Inputs!$B$5 -> 0 | D24: =MAX(0,D$4*Inputs!$B$40-Inputs!$B$9*Inputs!$B$41)*Inputs!$B$5 -> 0 | E24: =MAX(0,E$4*Inputs!$B$40-Inputs!$B$9*Inputs!$B$41)*Inputs!$B$5 -> 645 | F24: =MAX(0,F$4*Inputs!$B$40-Inputs!$B$9*Inputs!$B$41)*Inputs!$B$5 -> 3870
A25: Supabase compute upgrade | B25: =IF(B$4>Inputs!$B$44,Inputs!$B$45,IF(B$4>Inputs!$B$42,Inputs!$B$43,0))*Inputs!$B$5 -> 0 | C25: =IF(C$4>Inputs!$B$44,Inputs!$B$45,IF(C$4>Inputs!$B$42,Inputs!$B$43,0))*Inputs!$B$5 -> 0 | D25: =IF(D$4>Inputs!$B$44,Inputs!$B$45,IF(D$4>Inputs!$B$42,Inputs!$B$43,0))*Inputs!$B$5 -> 645 | E25: =IF(E$4>Inputs!$B$44,Inputs!$B$45,IF(E$4>Inputs!$B$42,Inputs!$B$43,0))*Inputs!$B$5 -> 645 | F25: =IF(F$4>Inputs!$B$44,Inputs!$B$45,IF(F$4>Inputs!$B$42,Inputs!$B$43,0))*Inputs!$B$5 -> 6450
A26: Total variable costs | B26: =SUM(B20:B25) -> 2110.2 | C26: =SUM(C20:C25) -> 10551 | D26: =SUM(D20:D25) -> 27090.225 | E26: =SUM(E20:E25) -> 54483.6 | F26: =SUM(F20:F25) -> 117107.1
A28: Result
A29: Total costs | B29: =B17+B26 -> 10081.867 | C29: =C17+C26 -> 18522.667 | D29: =D17+D26 -> 35061.892 | E29: =E17+E26 -> 62455.267 | F29: =F17+F26 -> 125078.77
A30: Profit before marketing | B30: =B8-B29 -> 13944.623 | C30: =C8-C29 -> 101609.78 | D30: =D8-D29 -> 265269.23 | E30: =E8-E29 -> 538206.98 | F30: =F8-F29 -> 1076245.7
A31: Profit margin | B31: =IF(B6=0,0,B30/B6) -> 0.57196978 | C31: =IF(C6=0,0,C30/C6) -> 0.83355031 | D31: =IF(D6=0,0,D30/D6) -> 0.87044867 | E31: =IF(E6=0,0,E30/E6) -> 0.88303033 | F31: =IF(F6=0,0,F30/F6) -> 0.88289232
A32: Cost per store | B32: =IF(B$4=0,0,B29/B$4) -> 504.09333 | C32: =IF(C$4=0,0,C29/C$4) -> 185.22667 | D32: =IF(D$4=0,0,D29/D$4) -> 140.24757 | E32: =IF(E$4=0,0,E29/E$4) -> 124.91053 | F32: =IF(F$4=0,0,F29/F$4) -> 125.07877
A33: SMS as a share of all costs | B33: =IF(B29=0,0,B20/B29) -> 0.20162933 | C33: =IF(C29=0,0,C20/C29) -> 0.54873308 | D33: =IF(D29=0,0,D20/D29) -> 0.72471846 | E33: =IF(E29=0,0,E20/E29) -> 0.81370239 | F33: =IF(F29=0,0,F20/F29) -> 0.81260795
A35: Break-even: paying stores needed to cover fixed costs | B35: =IF((Inputs!$B$22*(1-Inputs!$B$6)-B26/B4)<=0,0,ROUNDUP(B17/(Inputs!$B$22*(1-Inputs!$B$6)-B26/B4),0)) -> 8 | C35: stores, at the blended price and the 20-store cost per store
A36: Profit here is before marketing spend. Salaries count only if entered on the Inputs tab.

Sheet Per Plan
A1: What each plan earns per store per month (৳)
A2: Calculated from the Inputs tab. Shows whether each price covers its own costs.
A4: Plan | B4: =Inputs!A19 -> Starter | C4: =Inputs!A20 -> Pro | D4: =Inputs!A21 -> Business
A5: Price | B5: =Inputs!B19 -> 699 | C5: =Inputs!B20 -> 1499 | D5: =Inputs!B21 -> 3499
A6: bKash cash-out charge | B6: =B5*Inputs!$B$6 -> 10.1355 | C6: =C5*Inputs!$B$6 -> 21.7355 | D6: =D5*Inputs!$B$6 -> 50.7355
A7: SMS cost (after stores on own account) | B7: =Inputs!D19*Inputs!$B$26*Inputs!$B$25*(1-Inputs!$B$27) -> 50.4 | C7: =Inputs!D20*Inputs!$B$26*Inputs!$B$25*(1-Inputs!$B$27) -> 126 | D7: =Inputs!D21*Inputs!$B$26*Inputs!$B$25*(1-Inputs!$B$27) -> 336
A8: Email cost | B8: =Inputs!$B$30/1000*Inputs!$B$31*Inputs!$B$5 -> 3.87 | C8: =Inputs!$B$30/1000*Inputs!$B$31*Inputs!$B$5 -> 3.87 | D8: =Inputs!$B$30/1000*Inputs!$B$31*Inputs!$B$5 -> 3.87
A9: Variable cost per store | B9: =SUM(B6:B8) -> 64.4055 | C9: =SUM(C6:C8) -> 151.6055 | D9: =SUM(D6:D8) -> 390.6055
A10: Contribution per store | B10: =B5-B9 -> 634.5945 | C10: =C5-C9 -> 1347.3945 | D10: =D5-D9 -> 3108.3945
A11: Contribution margin | B11: =IF(B5=0,0,B10/B5) -> 0.90786052 | C11: =IF(C5=0,0,C10/C5) -> 0.89886224 | D11: =IF(D5=0,0,D10/D5) -> 0.88836653
A12: Share of fixed costs per store, at 100 stores | B12: ='Cost Model'!$C$17/'Cost Model'!$C$4 -> 79.716667 | C12: ='Cost Model'!$C$17/'Cost Model'!$C$4 -> 79.716667 | D12: ='Cost Model'!$C$17/'Cost Model'!$C$4 -> 79.716667
A13: Profit per store, at 100 stores | B13: =B10-B12 -> 554.87783 | C13: =C10-C12 -> 1267.6778 | D13: =D10-D12 -> 3028.6778
A14: Stores needed on this plan alone to break even | B14: =IF(B10<=0,0,ROUNDUP('Cost Model'!$B$17/B10,0)) -> 13 | C14: =IF(C10<=0,0,ROUNDUP('Cost Model'!$B$17/C10,0)) -> 6 | D14: =IF(D10<=0,0,ROUNDUP('Cost Model'!$B$17/D10,0)) -> 3
A16: Fixed-cost share uses the 100-store column of the Cost Model tab.

Sheet Sources
A1: Sources (opened 14 Oct 2026)
A3: Your answers in chat, 14 Oct 2026 | B3: Vercel, Supabase, SMS price, seats, exchange rate, domains, cash-out charge, tools, VAT
A4: Amazon SES pricing (CarlyEmail) | B4: https://www.usecarly.com/blog/amazon-ses-pricing/
A5: Resend pricing (Automation Atlas) | B5: https://automationatlas.io/answers/resend-pricing-explained-2026/
A6: Supabase pricing (Focus Reactive) | B6: https://focusreactive.com/blog/supabase-price/
A7: Vercel cost 2026 (MakerKit) | B7: https://makerkit.dev/blog/saas/vercel-cost
A8: Arafat Labs: Facebook ads cost Bangladesh 2026 | B8: https://arafatlabs.com/blog/facebook-ads-cost-bangladesh-2026-benchmarks
A9: KuiperZ: Bangladesh Facebook ads 2025 benchmarks | B9: https://kuiperz.io/blog/bangladesh-facebook-ads-2025-cost-benchmarks-ctr-cpa-ranges-and-a-simple-budget-calculator/
A10: Flint: B2B SaaS free trial conversion statistics (Apr 2026) | B10: https://www.flint.com/blog/b2b-saas-free-trial-conversion-rate-statistics
A11: Google Search CPC | B11: No published Bangladesh figure found; ৳25 is an estimate. Check Google Keyword Planner

Sheet Ad Benchmarks
A1: Ad benchmarks and funnel rates (Bangladesh, ৳)
A2: Blue = input, yellow = estimate to replace with your own ad results after 2-4 weeks. Black = calculated.
A4: Channel | B4: Meta prospecting | C4: Meta retargeting | D4: Google Search | E4: YouTube awareness | F4: Source / note
A5: Share of ad budget | B5: 0.55 | C5: 0.15 | D5: 0.25 | E5: 0.05 | F5: =SUM(B5:E5) -> 1 | G5: must equal 100%
A6: CPM (cost per 1,000 impressions) | B6: 350 | C6: 250 | D6: =D8*D7*1000 -> 1250 | E6: 150 | F6: Meta: Arafat Labs 2026 B2B/SaaS CPM ৳300-450, market ৳180-250. YouTube CPM is an estimate
A7: CTR (click-through rate) | B7: 0.015 | C7: 0.03 | D7: 0.05 | E7: 0.005 | F7: KuiperZ 2025: 1-4% typical, >2% strong cold, ~5% remarketing. Search 5% is an estimate
A8: CPC (cost per click) | B8: =B6/(1000*B7) -> 23.333333 | C8: =C6/(1000*C7) -> 8.3333333 | D8: 25 | E8: =E6/(1000*E7) -> 30 | F8: Google Search CPC ৳25 is an ESTIMATE (no published BD figure found). Check Google Keyword Planner
A9: Click → trial sign-up | B9: 0.03 | C9: 0.08 | D9: 0.06 | E9: 0 | F9: KuiperZ: B2B ~1%, warm ~5%; Flint 2026: paid visitor-to-trial 7.1%. YouTube = awareness only
A10: Trial → paid | B10: 0.15 | C10: 0.15 | D10: 0.2 | E10: 0.15 | F10: Flint 2026: no-card trial-to-paid 17.4% from paid traffic; 15% used as the base
A11: Cost per trial (CPL) | B11: =IFERROR(B8/B9,0) -> 777.77778 | C11: =IFERROR(C8/C9,0) -> 104.16667 | D11: =IFERROR(D8/D9,0) -> 416.66667 | E11: =IFERROR(E8/E9,0) -> 0 | F11: Arafat Labs: B2B/SaaS cost per lead ৳400-1,200, so Meta prospecting sits in range
A12: Cost per paid store (CAC) | B12: =IFERROR(B11/B10,0) -> 5185.1852 | C12: =IFERROR(C11/C10,0) -> 694.44444 | D12: =IFERROR(D11/D10,0) -> 2083.3333 | E12: =IFERROR(E11/E10,0) -> 0
A13: First-month ROAS | B13: =IFERROR(Inputs!$B$22/B12,0) -> 0.23509286 | C13: =IFERROR(Inputs!$B$22/C12,0) -> 1.75536 | D13: =IFERROR(Inputs!$B$22/D12,0) -> 0.58512 | E13: =IFERROR(Inputs!$B$22/E12,0) -> 0 | F13: Revenue in the first paid month ÷ cost to win that store. SaaS earns it back over many months
A15: Other forecast inputs
A16: Ad performance factor (scenario) | B16: 1 | F16: 100% = base. Try 70% (bad case) or 130% (good case); scales every ad sign-up
A17: Organic, partner and referral trial → paid | B17: 0.25 | F17: Warmer leads convert better than ads. Estimate
A18: Monthly churn (paying stores that leave) | B18: 0.04 | F18: Target from the strategy doc. Small-business SaaS often runs 3-7%
A19: Partner and referral commission | B19: 0.05 | F19: Share of total revenue paid to agencies and referrers. Estimate
A20: Revenue per paid store over its first 12 months | B20: =Inputs!$B$22*(1-(1-B18)^12)/B18 -> 11802.67 | F20: Price × expected months stayed in year one, after churn
A21: Lifetime contribution per store (LTV) | B21: =(Inputs!$B$22*(1-Inputs!$B$6)-((1-Inputs!$B$27)*Inputs!$D$22*Inputs!$B$26*Inputs!$B$25+Inputs!$B$30/1000*Inputs!$B$31*Inputs!$B$5))/B18 -> 27395.362 | F21: (Price - cash-out - SMS - email) ÷ churn
A22: Contribution per store per month | B22: =B21*B18 -> 1095.8145

Sheet Marketing Budget
A1: Suggested marketing budget by month (৳)
A2: Blue rows are your budget. Change them and the Forecast and Summary tabs update.
A4: Month | B4: Nov 2026 | C4: Dec 2026 | D4: Jan 2027 | E4: Feb 2027 | F4: Mar 2027 | G4: Apr 2027 | H4: May 2027 | I4: Jun 2027 | J4: Jul 2027 | K4: Aug 2027 | L4: Sep 2027 | M4: Oct 2027 | N4: 12-month total | O4: Why
A5: Paid ads
A6: Total ad budget | B6: 15000 | C6: 25000 | D6: 50000 | E6: 70000 | F6: 60000 | G6: 60000 | H6: 80000 | I6: 70000 | J6: 90000 | K6: 100000 | L6: 110000 | M6: 120000 | N6: =SUM(B6:M6) -> 850000 | O6: Small tests first; peaks before Eid-ul-Fitr (Feb) and Eid-ul-Adha (May); grows once CAC is proven
A7: Meta prospecting | B7: =B$6*'Ad Benchmarks'!$B$5 -> 8250 | C7: =C$6*'Ad Benchmarks'!$B$5 -> 13750 | D7: =D$6*'Ad Benchmarks'!$B$5 -> 27500 | E7: =E$6*'Ad Benchmarks'!$B$5 -> 38500 | F7: =F$6*'Ad Benchmarks'!$B$5 -> 33000 | G7: =G$6*'Ad Benchmarks'!$B$5 -> 33000 | H7: =H$6*'Ad Benchmarks'!$B$5 -> 44000 | I7: =I$6*'Ad Benchmarks'!$B$5 -> 38500 | ... M7: =M$6*'Ad Benchmarks'!$B$5 -> 66000 | N7: =SUM(B7:M7) -> 467500
A8: Meta retargeting | B8: =B$6*'Ad Benchmarks'!$C$5 -> 2250 | C8: =C$6*'Ad Benchmarks'!$C$5 -> 3750 | D8: =D$6*'Ad Benchmarks'!$C$5 -> 7500 | E8: =E$6*'Ad Benchmarks'!$C$5 -> 10500 | F8: =F$6*'Ad Benchmarks'!$C$5 -> 9000 | G8: =G$6*'Ad Benchmarks'!$C$5 -> 9000 | H8: =H$6*'Ad Benchmarks'!$C$5 -> 12000 | I8: =I$6*'Ad Benchmarks'!$C$5 -> 10500 | ... M8: =M$6*'Ad Benchmarks'!$C$5 -> 18000 | N8: =SUM(B8:M8) -> 127500
A9: Google Search | B9: =B$6*'Ad Benchmarks'!$D$5 -> 3750 | C9: =C$6*'Ad Benchmarks'!$D$5 -> 6250 | D9: =D$6*'Ad Benchmarks'!$D$5 -> 12500 | E9: =E$6*'Ad Benchmarks'!$D$5 -> 17500 | F9: =F$6*'Ad Benchmarks'!$D$5 -> 15000 | G9: =G$6*'Ad Benchmarks'!$D$5 -> 15000 | H9: =H$6*'Ad Benchmarks'!$D$5 -> 20000 | I9: =I$6*'Ad Benchmarks'!$D$5 -> 17500 | ... M9: =M$6*'Ad Benchmarks'!$D$5 -> 30000 | N9: =SUM(B9:M9) -> 212500
A10: YouTube awareness | B10: =B$6*'Ad Benchmarks'!$E$5 -> 750 | C10: =C$6*'Ad Benchmarks'!$E$5 -> 1250 | D10: =D$6*'Ad Benchmarks'!$E$5 -> 2500 | E10: =E$6*'Ad Benchmarks'!$E$5 -> 3500 | F10: =F$6*'Ad Benchmarks'!$E$5 -> 3000 | G10: =G$6*'Ad Benchmarks'!$E$5 -> 3000 | H10: =H$6*'Ad Benchmarks'!$E$5 -> 4000 | I10: =I$6*'Ad Benchmarks'!$E$5 -> 3500 | ... M10: =M$6*'Ad Benchmarks'!$E$5 -> 6000 | N10: =SUM(B10:M10) -> 42500
A11: Other marketing
A12: Content production (designer, video editor) | B12: 15000 | C12: 15000 | D12: 15000 | E12: 15000 | F12: 15000 | G12: 15000 | H12: 15000 | I12: 15000 | J12: 15000 | K12: 15000 | L12: 15000 | M12: 15000 | N12: =SUM(B12:M12) -> 180000 | O12: Freelance designer and editor for posts and short videos
A13: Tools (Canva Pro, scheduling) | B13: 1000 | C13: 1000 | D13: 1000 | E13: 1000 | F13: 1000 | G13: 1000 | H13: 1000 | I13: 1000 | J13: 1000 | K13: 1000 | L13: 1000 | M13: 1000 | N13: =SUM(B13:M13) -> 12000 | O13: Estimate
A14: Creators and seller influencers | B14: 0 | C14: 0 | D14: 10000 | E14: 10000 | F14: 10000 | G14: 10000 | H14: 10000 | I14: 10000 | J14: 10000 | K14: 10000 | L14: 10000 | M14: 10000 | N14: =SUM(B14:M14) -> 100000 | O14: Micro-creators who teach online selling, from January
A15: Events, pop-up desks, challenge prizes | B15: 0 | C15: 0 | D15: 0 | E15: 30000 | F15: 0 | G15: 20000 | H15: 0 | I15: 0 | J15: 20000 | K15: 0 | L15: 20000 | M15: 0 | N15: =SUM(B15:M15) -> 90000 | O15: Eid Ready challenge (Feb), wholesale-market desks
A16: Founding-merchant discounts | B16: 6990 | C16: 6990 | D16: 6990 | E16: 6990 | F16: 0 | G16: 0 | H16: 0 | I16: 0 | J16: 0 | K16: 0 | L16: 0 | M16: 0 | N16: =SUM(B16:M16) -> 27960 | O16: 20 stores × ৳699 × 50% for the first months
A17: Partner and referral commissions | B17: =Forecast!B25*'Ad Benchmarks'!$B$19 -> 0 | C17: =Forecast!C25*'Ad Benchmarks'!$B$19 -> 708.9138 | D17: =Forecast!D25*'Ad Benchmarks'!$B$19 -> 1735.1011 | E17: =Forecast!E25*'Ad Benchmarks'!$B$19 -> 3622.4097 | F17: =Forecast!F25*'Ad Benchmarks'!$B$19 -> 6125.4861 | G17: =Forecast!G25*'Ad Benchmarks'!$B$19 -> 8182.8094 | H17: =Forecast!H25*'Ad Benchmarks'!$B$19 -> 10234.027 | I17: =Forecast!I25*'Ad Benchmarks'!$B$19 -> 12894.456 | ... M17: =Forecast!M25*'Ad Benchmarks'!$B$19 -> 24739.428 | N17: =SUM(B17:M17) -> 122739.49 | O17: Calculated: % of revenue (Ad Benchmarks tab)
A18: Total marketing spend | B18: =B6+SUM(B12:B17) -> 37990 | C18: =C6+SUM(C12:C17) -> 48698.914 | D18: =D6+SUM(D12:D17) -> 84725.101 | E18: =E6+SUM(E12:E17) -> 136612.41 | F18: =F6+SUM(F12:F17) -> 92125.486 | G18: =G6+SUM(G12:G17) -> 114182.81 | H18: =H6+SUM(H12:H17) -> 116234.03 | I18: =I6+SUM(I12:I17) -> 108894.46 | ... M18: =M6+SUM(M12:M17) -> 170739.43 | N18: =SUM(B18:M18) -> 1382699.5
A19: Meta total (prospecting + retargeting) | B19: =B7+B8 -> 10500 | C19: =C7+C8 -> 17500 | D19: =D7+D8 -> 35000 | E19: =E7+E8 -> 49000 | F19: =F7+F8 -> 42000 | G19: =G7+G8 -> 42000 | H19: =H7+H8 -> 56000 | I19: =I7+I8 -> 49000 | ... N19: =N7+N8 -> 595000
A20: Google total (Search + YouTube) | B20: =B9+B10 -> 4500 | C20: =C9+C10 -> 7500 | D20: =D9+D10 -> 15000 | E20: =E9+E10 -> 21000 | F20: =F9+F10 -> 18000 | G20: =G9+G10 -> 18000 | H20: =H9+H10 -> 24000 | I20: =I9+I10 -> 21000 | ... N20: =N9+N10 -> 255000

Sheet Forecast
A1: 12-month forecast: ads → trials → paying stores → profit (৳)
A2: Trials convert to paid the month after sign-up (14-day trial). Salaries are included only if entered on the Inputs tab.
A4: Month | B4: Nov 2026 | C4: Dec 2026 | D4: Jan 2027 | E4: Feb 2027 | F4: Mar 2027 | G4: Apr 2027 | H4: May 2027 | I4: Jun 2027 | J4: Jul 2027 | K4: Aug 2027 | L4: Sep 2027 | M4: Oct 2027 | N4: 12-month total
A5: Reach and traffic (paid ads)
A6: Ad spend | B6: ='Marketing Budget'!B6 -> 15000 | C6: ='Marketing Budget'!C6 -> 25000 | D6: ='Marketing Budget'!D6 -> 50000 | E6: ='Marketing Budget'!E6 -> 70000 | F6: ='Marketing Budget'!F6 -> 60000 | G6: ='Marketing Budget'!G6 -> 60000 | H6: ='Marketing Budget'!H6 -> 80000 | I6: ='Marketing Budget'!I6 -> 70000 | ... M6: ='Marketing Budget'!M6 -> 120000 | N6: =SUM(B6:M6) -> 850000
A7: Impressions | B7: =('Marketing Budget'!B7/'Ad Benchmarks'!$B$6+'Marketing Budget'!B8/'Ad Benchmarks'!$C$6+'Marketing Budget'!B9/'Ad Benchmarks'!$D$6+'Marketing Budget'!B10/'Ad Benchmarks'!$E$6)*1000 -> 40571.429 | C7: =('Marketing Budget'!C7/'Ad Benchmarks'!$B$6+'Marketing Budget'!C8/'Ad Benchmarks'!$C$6+'Marketing Budget'!C9/'Ad Benchmarks'!$D$6+'Marketing Budget'!C10/'Ad Benchmarks'!$E$6)*1000 -> 67619.048 | D7: =('Marketing Budget'!D7/'Ad Benchmarks'!$B$6+'Marketing Budget'!D8/'Ad Benchmarks'!$C$6+'Marketing Budget'!D9/'Ad Benchmarks'!$D$6+'Marketing Budget'!D10/'Ad Benchmarks'!$E$6)*1000 -> 135238.1 | E7: =('Marketing Budget'!E7/'Ad Benchmarks'!$B$6+'Marketing Budget'!E8/'Ad Benchmarks'!$C$6+'Marketing Budget'!E9/'Ad Benchmarks'!$D$6+'Marketing Budget'!E10/'Ad Benchmarks'!$E$6)*1000 -> 189333.33 | F7: =('Marketing Budget'!F7/'Ad Benchmarks'!$B$6+'Marketing Budget'!F8/'Ad Benchmarks'!$C$6+'Marketing Budget'!F9/'Ad Benchmarks'!$D$6+'Marketing Budget'!F10/'Ad Benchmarks'!$E$6)*1000 -> 162285.71 | G7: =('Marketing Budget'!G7/'Ad Benchmarks'!$B$6+'Marketing Budget'!G8/'Ad Benchmarks'!$C$6+'Marketing Budget'!G9/'Ad Benchmarks'!$D$6+'Marketing Budget'!G10/'Ad Benchmarks'!$E$6)*1000 -> 162285.71 | H7: =('Marketing Budget'!H7/'Ad Benchmarks'!$B$6+'Marketing Budget'!H8/'Ad Benchmarks'!$C$6+'Marketing Budget'!H9/'Ad Benchmarks'!$D$6+'Marketing Budget'!H10/'Ad Benchmarks'!$E$6)*1000 -> 216380.95 | I7: =('Marketing Budget'!I7/'Ad Benchmarks'!$B$6+'Marketing Budget'!I8/'Ad Benchmarks'!$C$6+'Marketing Budget'!I9/'Ad Benchmarks'!$D$6+'Marketing Budget'!I10/'Ad Benchmarks'!$E$6)*1000 -> 189333.33 | ... M7: =('Marketing Budget'!M7/'Ad Benchmarks'!$B$6+'Marketing Budget'!M8/'Ad Benchmarks'!$C$6+'Marketing Budget'!M9/'Ad Benchmarks'!$D$6+'Marketing Budget'!M10/'Ad Benchmarks'!$E$6)*1000 -> 324571.43 | N7: =SUM(B7:M7) -> 2299047.6
A8: Clicks | B8: ='Marketing Budget'!B7/'Ad Benchmarks'!$B$8+'Marketing Budget'!B8/'Ad Benchmarks'!$C$8+'Marketing Budget'!B9/'Ad Benchmarks'!$D$8+'Marketing Budget'!B10/'Ad Benchmarks'!$E$8 -> 798.57143 | C8: ='Marketing Budget'!C7/'Ad Benchmarks'!$B$8+'Marketing Budget'!C8/'Ad Benchmarks'!$C$8+'Marketing Budget'!C9/'Ad Benchmarks'!$D$8+'Marketing Budget'!C10/'Ad Benchmarks'!$E$8 -> 1330.9524 | D8: ='Marketing Budget'!D7/'Ad Benchmarks'!$B$8+'Marketing Budget'!D8/'Ad Benchmarks'!$C$8+'Marketing Budget'!D9/'Ad Benchmarks'!$D$8+'Marketing Budget'!D10/'Ad Benchmarks'!$E$8 -> 2661.9048 | E8: ='Marketing Budget'!E7/'Ad Benchmarks'!$B$8+'Marketing Budget'!E8/'Ad Benchmarks'!$C$8+'Marketing Budget'!E9/'Ad Benchmarks'!$D$8+'Marketing Budget'!E10/'Ad Benchmarks'!$E$8 -> 3726.6667 | F8: ='Marketing Budget'!F7/'Ad Benchmarks'!$B$8+'Marketing Budget'!F8/'Ad Benchmarks'!$C$8+'Marketing Budget'!F9/'Ad Benchmarks'!$D$8+'Marketing Budget'!F10/'Ad Benchmarks'!$E$8 -> 3194.2857 | G8: ='Marketing Budget'!G7/'Ad Benchmarks'!$B$8+'Marketing Budget'!G8/'Ad Benchmarks'!$C$8+'Marketing Budget'!G9/'Ad Benchmarks'!$D$8+'Marketing Budget'!G10/'Ad Benchmarks'!$E$8 -> 3194.2857 | H8: ='Marketing Budget'!H7/'Ad Benchmarks'!$B$8+'Marketing Budget'!H8/'Ad Benchmarks'!$C$8+'Marketing Budget'!H9/'Ad Benchmarks'!$D$8+'Marketing Budget'!H10/'Ad Benchmarks'!$E$8 -> 4259.0476 | I8: ='Marketing Budget'!I7/'Ad Benchmarks'!$B$8+'Marketing Budget'!I8/'Ad Benchmarks'!$C$8+'Marketing Budget'!I9/'Ad Benchmarks'!$D$8+'Marketing Budget'!I10/'Ad Benchmarks'!$E$8 -> 3726.6667 | ... M8: ='Marketing Budget'!M7/'Ad Benchmarks'!$B$8+'Marketing Budget'!M8/'Ad Benchmarks'!$C$8+'Marketing Budget'!M9/'Ad Benchmarks'!$D$8+'Marketing Budget'!M10/'Ad Benchmarks'!$E$8 -> 6388.5714 | N8: =SUM(B8:M8) -> 45252.381
A9: Blended CPM | B9: =IFERROR(B6/B7*1000,0) -> 369.71831 | C9: =IFERROR(C6/C7*1000,0) -> 369.71831 | D9: =IFERROR(D6/D7*1000,0) -> 369.71831 | E9: =IFERROR(E6/E7*1000,0) -> 369.71831 | F9: =IFERROR(F6/F7*1000,0) -> 369.71831 | G9: =IFERROR(G6/G7*1000,0) -> 369.71831 | H9: =IFERROR(H6/H7*1000,0) -> 369.71831 | I9: =IFERROR(I6/I7*1000,0) -> 369.71831 | ... N9: =IFERROR(N6/N7*1000,0) -> 369.71831
A10: Blended CPC | B10: =IFERROR(B6/B8,0) -> 18.783542 | C10: =IFERROR(C6/C8,0) -> 18.783542 | D10: =IFERROR(D6/D8,0) -> 18.783542 | E10: =IFERROR(E6/E8,0) -> 18.783542 | F10: =IFERROR(F6/F8,0) -> 18.783542 | G10: =IFERROR(G6/G8,0) -> 18.783542 | H10: =IFERROR(H6/H8,0) -> 18.783542 | I10: =IFERROR(I6/I8,0) -> 18.783542 | ... N10: =IFERROR(N6/N8,0) -> 18.783542
A11: Blended CTR | B11: =IFERROR(B8/B7,0) -> 0.019683099 | C11: =IFERROR(C8/C7,0) -> 0.019683099 | D11: =IFERROR(D8/D7,0) -> 0.019683099 | E11: =IFERROR(E8/E7,0) -> 0.019683099 | F11: =IFERROR(F8/F7,0) -> 0.019683099 | G11: =IFERROR(G8/G7,0) -> 0.019683099 | H11: =IFERROR(H8/H7,0) -> 0.019683099 | I11: =IFERROR(I8/I7,0) -> 0.019683099 | ... N11: =IFERROR(N8/N7,0) -> 0.019683099
A12: Trial sign-ups
A13: From Meta prospecting | B13: ='Marketing Budget'!B7/'Ad Benchmarks'!$B$8*'Ad Benchmarks'!$B$9*'Ad Benchmarks'!$B$16 -> 10.607143 | C13: ='Marketing Budget'!C7/'Ad Benchmarks'!$B$8*'Ad Benchmarks'!$B$9*'Ad Benchmarks'!$B$16 -> 17.678571 | D13: ='Marketing Budget'!D7/'Ad Benchmarks'!$B$8*'Ad Benchmarks'!$B$9*'Ad Benchmarks'!$B$16 -> 35.357143 | E13: ='Marketing Budget'!E7/'Ad Benchmarks'!$B$8*'Ad Benchmarks'!$B$9*'Ad Benchmarks'!$B$16 -> 49.5 | F13: ='Marketing Budget'!F7/'Ad Benchmarks'!$B$8*'Ad Benchmarks'!$B$9*'Ad Benchmarks'!$B$16 -> 42.428571 | G13: ='Marketing Budget'!G7/'Ad Benchmarks'!$B$8*'Ad Benchmarks'!$B$9*'Ad Benchmarks'!$B$16 -> 42.428571 | H13: ='Marketing Budget'!H7/'Ad Benchmarks'!$B$8*'Ad Benchmarks'!$B$9*'Ad Benchmarks'!$B$16 -> 56.571429 | I13: ='Marketing Budget'!I7/'Ad Benchmarks'!$B$8*'Ad Benchmarks'!$B$9*'Ad Benchmarks'!$B$16 -> 49.5 | ... M13: ='Marketing Budget'!M7/'Ad Benchmarks'!$B$8*'Ad Benchmarks'!$B$9*'Ad Benchmarks'!$B$16 -> 84.857143 | N13: =SUM(B13:M13) -> 601.07143
A14: From Meta retargeting | B14: ='Marketing Budget'!B8/'Ad Benchmarks'!$C$8*'Ad Benchmarks'!$C$9*'Ad Benchmarks'!$B$16 -> 21.6 | C14: ='Marketing Budget'!C8/'Ad Benchmarks'!$C$8*'Ad Benchmarks'!$C$9*'Ad Benchmarks'!$B$16 -> 36 | D14: ='Marketing Budget'!D8/'Ad Benchmarks'!$C$8*'Ad Benchmarks'!$C$9*'Ad Benchmarks'!$B$16 -> 72 | E14: ='Marketing Budget'!E8/'Ad Benchmarks'!$C$8*'Ad Benchmarks'!$C$9*'Ad Benchmarks'!$B$16 -> 100.8 | F14: ='Marketing Budget'!F8/'Ad Benchmarks'!$C$8*'Ad Benchmarks'!$C$9*'Ad Benchmarks'!$B$16 -> 86.4 | G14: ='Marketing Budget'!G8/'Ad Benchmarks'!$C$8*'Ad Benchmarks'!$C$9*'Ad Benchmarks'!$B$16 -> 86.4 | H14: ='Marketing Budget'!H8/'Ad Benchmarks'!$C$8*'Ad Benchmarks'!$C$9*'Ad Benchmarks'!$B$16 -> 115.2 | I14: ='Marketing Budget'!I8/'Ad Benchmarks'!$C$8*'Ad Benchmarks'!$C$9*'Ad Benchmarks'!$B$16 -> 100.8 | ... M14: ='Marketing Budget'!M8/'Ad Benchmarks'!$C$8*'Ad Benchmarks'!$C$9*'Ad Benchmarks'!$B$16 -> 172.8 | N14: =SUM(B14:M14) -> 1224
A15: From Google Search | B15: ='Marketing Budget'!B9/'Ad Benchmarks'!$D$8*'Ad Benchmarks'!$D$9*'Ad Benchmarks'!$B$16 -> 9 | C15: ='Marketing Budget'!C9/'Ad Benchmarks'!$D$8*'Ad Benchmarks'!$D$9*'Ad Benchmarks'!$B$16 -> 15 | D15: ='Marketing Budget'!D9/'Ad Benchmarks'!$D$8*'Ad Benchmarks'!$D$9*'Ad Benchmarks'!$B$16 -> 30 | E15: ='Marketing Budget'!E9/'Ad Benchmarks'!$D$8*'Ad Benchmarks'!$D$9*'Ad Benchmarks'!$B$16 -> 42 | F15: ='Marketing Budget'!F9/'Ad Benchmarks'!$D$8*'Ad Benchmarks'!$D$9*'Ad Benchmarks'!$B$16 -> 36 | G15: ='Marketing Budget'!G9/'Ad Benchmarks'!$D$8*'Ad Benchmarks'!$D$9*'Ad Benchmarks'!$B$16 -> 36 | H15: ='Marketing Budget'!H9/'Ad Benchmarks'!$D$8*'Ad Benchmarks'!$D$9*'Ad Benchmarks'!$B$16 -> 48 | I15: ='Marketing Budget'!I9/'Ad Benchmarks'!$D$8*'Ad Benchmarks'!$D$9*'Ad Benchmarks'!$B$16 -> 42 | ... M15: ='Marketing Budget'!M9/'Ad Benchmarks'!$D$8*'Ad Benchmarks'!$D$9*'Ad Benchmarks'!$B$16 -> 72 | N15: =SUM(B15:M15) -> 510
A16: Organic, partner and referral (your target) | B16: 20 | C16: 25 | D16: 40 | E16: 50 | F16: 45 | G16: 50 | H16: 60 | I16: 60 | J16: 70 | K16: 80 | L16: 90 | M16: 100 | N16: =SUM(B16:M16) -> 690
A17: Total trial sign-ups | B17: =SUM(B13:B16) -> 61.207143 | C17: =SUM(C13:C16) -> 93.678571 | D17: =SUM(D13:D16) -> 177.35714 | E17: =SUM(E13:E16) -> 242.3 | F17: =SUM(F13:F16) -> 209.82857 | G17: =SUM(G13:G16) -> 214.82857 | H17: =SUM(H13:H16) -> 279.77143 | I17: =SUM(I13:I16) -> 252.3 | ... M17: =SUM(M13:M16) -> 429.65714 | N17: =SUM(B17:M17) -> 3025.0714
A18: Cost per trial from ads (CPL) | B18: =IFERROR(B6/SUM(B13:B15),0) -> 364.01456 | C18: =IFERROR(C6/SUM(C13:C15),0) -> 364.01456 | D18: =IFERROR(D6/SUM(D13:D15),0) -> 364.01456 | E18: =IFERROR(E6/SUM(E13:E15),0) -> 364.01456 | F18: =IFERROR(F6/SUM(F13:F15),0) -> 364.01456 | G18: =IFERROR(G6/SUM(G13:G15),0) -> 364.01456 | H18: =IFERROR(H6/SUM(H13:H15),0) -> 364.01456 | I18: =IFERROR(I6/SUM(I13:I15),0) -> 364.01456 | ... N18: =IFERROR(N6/SUM(N13:N15),0) -> 364.01456
A19: Paying stores
A20: New paying stores from ads | B20: =0 -> 0 | C20: =B13*'Ad Benchmarks'!$B$10+B14*'Ad Benchmarks'!$C$10+B15*'Ad Benchmarks'!$D$10 -> 6.6310714 | D20: =C13*'Ad Benchmarks'!$B$10+C14*'Ad Benchmarks'!$C$10+C15*'Ad Benchmarks'!$D$10 -> 11.051786 | E20: =D13*'Ad Benchmarks'!$B$10+D14*'Ad Benchmarks'!$C$10+D15*'Ad Benchmarks'!$D$10 -> 22.103571 | F20: =E13*'Ad Benchmarks'!$B$10+E14*'Ad Benchmarks'!$C$10+E15*'Ad Benchmarks'!$D$10 -> 30.945 | G20: =F13*'Ad Benchmarks'!$B$10+F14*'Ad Benchmarks'!$C$10+F15*'Ad Benchmarks'!$D$10 -> 26.524286 | H20: =G13*'Ad Benchmarks'!$B$10+G14*'Ad Benchmarks'!$C$10+G15*'Ad Benchmarks'!$D$10 -> 26.524286 | I20: =H13*'Ad Benchmarks'!$B$10+H14*'Ad Benchmarks'!$C$10+H15*'Ad Benchmarks'!$D$10 -> 35.365714 | J20: =I13*'Ad Benchmarks'!$B$10+I14*'Ad Benchmarks'!$C$10+I15*'Ad Benchmarks'!$D$10 -> 30.945 | ... M20: =L13*'Ad Benchmarks'!$B$10+L14*'Ad Benchmarks'!$C$10+L15*'Ad Benchmarks'!$D$10 -> 48.627857 | N20: =SUM(B20:M20) -> 322.71214
A21: New paying stores from organic and partners | B21: =0 -> 0 | C21: =B16*'Ad Benchmarks'!$B$17 -> 5 | D21: =C16*'Ad Benchmarks'!$B$17 -> 6.25 | E21: =D16*'Ad Benchmarks'!$B$17 -> 10 | F21: =E16*'Ad Benchmarks'!$B$17 -> 12.5 | G21: =F16*'Ad Benchmarks'!$B$17 -> 11.25 | H21: =G16*'Ad Benchmarks'!$B$17 -> 12.5 | I21: =H16*'Ad Benchmarks'!$B$17 -> 15 | J21: =I16*'Ad Benchmarks'!$B$17 -> 15 | ... M21: =L16*'Ad Benchmarks'!$B$17 -> 22.5 | N21: =SUM(B21:M21) -> 147.5
A22: Stores that cancel (churn) | B22: =0 -> 0 | C22: =B24*'Ad Benchmarks'!$B$18 -> 0 | D22: =C24*'Ad Benchmarks'!$B$18 -> 0.46524286 | E22: =D24*'Ad Benchmarks'!$B$18 -> 1.1387046 | F22: =E24*'Ad Benchmarks'!$B$18 -> 2.3772992 | G22: =F24*'Ad Benchmarks'!$B$18 -> 4.0200073 | H22: =G24*'Ad Benchmarks'!$B$18 -> 5.3701784 | I22: =H24*'Ad Benchmarks'!$B$18 -> 6.7163427 | J22: =I24*'Ad Benchmarks'!$B$18 -> 8.4623176 | ... M22: =L24*'Ad Benchmarks'!$B$18 -> 13.948718 | N22: =SUM(B22:M22) -> 64.315053
A23: Net new paying stores | B23: =B20+B21-B22 -> 0 | C23: =C20+C21-C22 -> 11.631071 | D23: =D20+D21-D22 -> 16.836543 | E23: =E20+E21-E22 -> 30.964867 | F23: =F20+F21-F22 -> 41.067701 | G23: =G20+G21-G22 -> 33.754278 | H23: =H20+H21-H22 -> 33.654107 | I23: =I20+I21-I22 -> 43.649372 | ... M23: =M20+M21-M22 -> 57.179139 | N23: =SUM(B23:M23) -> 405.89709
A24: Paying stores at month end | B24: =B23 -> 0 | C24: =B24+C23 -> 11.631071 | D24: =C24+D23 -> 28.467614 | E24: =D24+E23 -> 59.432481 | F24: =E24+F23 -> 100.50018 | G24: =F24+G23 -> 134.25446 | H24: =G24+H23 -> 167.90857 | I24: =H24+I23 -> 211.55794 | J24: =I24+J23 -> 249.04062 | ... M24: =L24+M23 -> 405.89709 | N24: =M24 -> 405.89709
A25: Subscription revenue | B25: =B24*Inputs!$B$22 -> 0 | C25: =C24*Inputs!$B$22 -> 14178.276 | D25: =D24*Inputs!$B$22 -> 34702.022 | E25: =E24*Inputs!$B$22 -> 72448.195 | F25: =F24*Inputs!$B$22 -> 122509.72 | G25: =G24*Inputs!$B$22 -> 163656.19 | H25: =H24*Inputs!$B$22 -> 204680.54 | I25: =I24*Inputs!$B$22 -> 257889.13 | ... M25: =M24*Inputs!$B$22 -> 494788.55 | N25: =SUM(B25:M25) -> 2454789.8
A26: MRR at month end (monthly recurring revenue) | B26: =B24*Inputs!$B$22 -> 0 | C26: =C24*Inputs!$B$22 -> 14178.276 | D26: =D24*Inputs!$B$22 -> 34702.022 | E26: =E24*Inputs!$B$22 -> 72448.195 | F26: =F24*Inputs!$B$22 -> 122509.72 | G26: =G24*Inputs!$B$22 -> 163656.19 | H26: =H24*Inputs!$B$22 -> 204680.54 | I26: =I24*Inputs!$B$22 -> 257889.13 | ... M26: =M24*Inputs!$B$22 -> 494788.55 | N26: =M26 -> 494788.55
A27: Costs
A28: bKash cash-out charge | B28: =B25*Inputs!$B$6 -> 0 | C28: =C25*Inputs!$B$6 -> 205.585 | D28: =D25*Inputs!$B$6 -> 503.17932 | E28: =E25*Inputs!$B$6 -> 1050.4988 | F28: =F25*Inputs!$B$6 -> 1776.391 | G28: =G25*Inputs!$B$6 -> 2373.0147 | H28: =H25*Inputs!$B$6 -> 2967.8679 | I28: =I25*Inputs!$B$6 -> 3739.3924 | ... M28: =M25*Inputs!$B$6 -> 7174.434 | N28: =SUM(B28:M28) -> 35594.452
A29: Platform fixed costs (incl. salaries if entered) | B29: ='Cost Model'!$B$17 -> 7971.6667 | C29: ='Cost Model'!$B$17 -> 7971.6667 | D29: ='Cost Model'!$B$17 -> 7971.6667 | E29: ='Cost Model'!$B$17 -> 7971.6667 | F29: ='Cost Model'!$B$17 -> 7971.6667 | G29: ='Cost Model'!$B$17 -> 7971.6667 | H29: ='Cost Model'!$B$17 -> 7971.6667 | I29: ='Cost Model'!$B$17 -> 7971.6667 | ... M29: ='Cost Model'!$B$17 -> 7971.6667 | N29: =SUM(B29:M29) -> 95660
A30: SMS and email (paying stores) | B30: =B24*((1-Inputs!$B$27)*Inputs!$D$22*Inputs!$B$26*Inputs!$B$25+Inputs!$B$30/1000*Inputs!$B$31*Inputs!$B$5) -> 0 | C30: =C24*((1-Inputs!$B$27)*Inputs!$D$22*Inputs!$B$26*Inputs!$B$25+Inputs!$B$30/1000*Inputs!$B$31*Inputs!$B$5) -> 1227.1943 | D30: =D24*((1-Inputs!$B$27)*Inputs!$D$22*Inputs!$B$26*Inputs!$B$25+Inputs!$B$30/1000*Inputs!$B$31*Inputs!$B$5) -> 3003.618 | E30: =E24*((1-Inputs!$B$27)*Inputs!$D$22*Inputs!$B$26*Inputs!$B$25+Inputs!$B$30/1000*Inputs!$B$31*Inputs!$B$5) -> 6270.7211 | F30: =F24*((1-Inputs!$B$27)*Inputs!$D$22*Inputs!$B$26*Inputs!$B$25+Inputs!$B$30/1000*Inputs!$B$31*Inputs!$B$5) -> 10603.774 | G30: =G24*((1-Inputs!$B$27)*Inputs!$D$22*Inputs!$B$26*Inputs!$B$25+Inputs!$B$30/1000*Inputs!$B$31*Inputs!$B$5) -> 14165.188 | H30: =H24*((1-Inputs!$B$27)*Inputs!$D$22*Inputs!$B$26*Inputs!$B$25+Inputs!$B$30/1000*Inputs!$B$31*Inputs!$B$5) -> 17716.033 | I30: =I24*((1-Inputs!$B$27)*Inputs!$D$22*Inputs!$B$26*Inputs!$B$25+Inputs!$B$30/1000*Inputs!$B$31*Inputs!$B$5) -> 22321.478 | ... M30: =M24*((1-Inputs!$B$27)*Inputs!$D$22*Inputs!$B$26*Inputs!$B$25+Inputs!$B$30/1000*Inputs!$B$31*Inputs!$B$5) -> 42826.202 | N30: =SUM(B30:M30) -> 212473.23
A31: Marketing spend (all) | B31: ='Marketing Budget'!B18 -> 37990 | C31: ='Marketing Budget'!C18 -> 48698.914 | D31: ='Marketing Budget'!D18 -> 84725.101 | E31: ='Marketing Budget'!E18 -> 136612.41 | F31: ='Marketing Budget'!F18 -> 92125.486 | G31: ='Marketing Budget'!G18 -> 114182.81 | H31: ='Marketing Budget'!H18 -> 116234.03 | I31: ='Marketing Budget'!I18 -> 108894.46 | ... M31: ='Marketing Budget'!M18 -> 170739.43 | N31: =SUM(B31:M31) -> 1382699.5
A32: Total costs | B32: =SUM(B28:B31) -> 45961.667 | C32: =SUM(C28:C31) -> 58103.36 | D32: =SUM(D28:D31) -> 96203.565 | E32: =SUM(E28:E31) -> 151905.3 | F32: =SUM(F28:F31) -> 112477.32 | G32: =SUM(G28:G31) -> 138692.68 | H32: =SUM(H28:H31) -> 144889.59 | I32: =SUM(I28:I31) -> 142926.99 | ... M32: =SUM(M28:M31) -> 228711.73 | N32: =SUM(B32:M32) -> 1726427.2
A33: Result
A34: Profit or loss this month | B34: =B25-B32 -> -45961.667 | C34: =C25-C32 -> -43925.084 | D34: =D25-D32 -> -61501.543 | E34: =E25-E32 -> -79457.102 | F34: =F25-F32 -> 10032.404 | G34: =G25-G32 -> 24963.508 | H34: =H25-H32 -> 59790.949 | I34: =I25-I32 -> 114962.13 | ... M34: =M25-M32 -> 266076.82 | N34: =SUM(B34:M34) -> 728362.61
A35: Cumulative profit or loss (cash position) | B35: =B34 -> -45961.667 | C35: =B35+C34 -> -89886.75 | D35: =C35+D34 -> -151388.29 | E35: =D35+E34 -> -230845.4 | F35: =E35+F34 -> -220812.99 | G35: =F35+G34 -> -195849.48 | H35: =G35+H34 -> -136058.53 | I35: =H35+I34 -> -21096.4 | J35: =I35+J34 -> 92655.232 | ... M35: =L35+M34 -> 728362.61 | N35: =M35 -> 728362.61
A36: Return metrics
A37: CAC from ads (ad spend ÷ paying stores won) | B37: =IFERROR(B6/(B13*'Ad Benchmarks'!$B$10+B14*'Ad Benchmarks'!$C$10+B15*'Ad Benchmarks'!$D$10),0) -> 2262.0779 | C37: =IFERROR(C6/(C13*'Ad Benchmarks'!$B$10+C14*'Ad Benchmarks'!$C$10+C15*'Ad Benchmarks'!$D$10),0) -> 2262.0779 | D37: =IFERROR(D6/(D13*'Ad Benchmarks'!$B$10+D14*'Ad Benchmarks'!$C$10+D15*'Ad Benchmarks'!$D$10),0) -> 2262.0779 | E37: =IFERROR(E6/(E13*'Ad Benchmarks'!$B$10+E14*'Ad Benchmarks'!$C$10+E15*'Ad Benchmarks'!$D$10),0) -> 2262.0779 | F37: =IFERROR(F6/(F13*'Ad Benchmarks'!$B$10+F14*'Ad Benchmarks'!$C$10+F15*'Ad Benchmarks'!$D$10),0) -> 2262.0779 | G37: =IFERROR(G6/(G13*'Ad Benchmarks'!$B$10+G14*'Ad Benchmarks'!$C$10+G15*'Ad Benchmarks'!$D$10),0) -> 2262.0779 | H37: =IFERROR(H6/(H13*'Ad Benchmarks'!$B$10+H14*'Ad Benchmarks'!$C$10+H15*'Ad Benchmarks'!$D$10),0) -> 2262.0779 | I37: =IFERROR(I6/(I13*'Ad Benchmarks'!$B$10+I14*'Ad Benchmarks'!$C$10+I15*'Ad Benchmarks'!$D$10),0) -> 2262.0779 | ... N37: =IFERROR(N6/(N13*'Ad Benchmarks'!$B$10+N14*'Ad Benchmarks'!$C$10+N15*'Ad Benchmarks'!$D$10),0) -> 2262.0779
A38: CAC all-in (all marketing ÷ all paying stores won) | B38: =IFERROR(B31/((B13*'Ad Benchmarks'!$B$10+B14*'Ad Benchmarks'!$C$10+B15*'Ad Benchmarks'!$D$10)+B16*'Ad Benchmarks'!$B$17),0) -> 3266.2511 | C38: =IFERROR(C31/((C13*'Ad Benchmarks'!$B$10+C14*'Ad Benchmarks'!$C$10+C15*'Ad Benchmarks'!$D$10)+C16*'Ad Benchmarks'!$B$17),0) -> 2814.6756 | D38: =IFERROR(D31/((D13*'Ad Benchmarks'!$B$10+D14*'Ad Benchmarks'!$C$10+D15*'Ad Benchmarks'!$D$10)+D16*'Ad Benchmarks'!$B$17),0) -> 2639.1176 | E38: =IFERROR(E31/((E13*'Ad Benchmarks'!$B$10+E14*'Ad Benchmarks'!$C$10+E15*'Ad Benchmarks'!$D$10)+E16*'Ad Benchmarks'!$B$17),0) -> 3144.491 | F38: =IFERROR(F31/((F13*'Ad Benchmarks'!$B$10+F14*'Ad Benchmarks'!$C$10+F15*'Ad Benchmarks'!$D$10)+F16*'Ad Benchmarks'!$B$17),0) -> 2438.8412 | G38: =IFERROR(G31/((G13*'Ad Benchmarks'!$B$10+G14*'Ad Benchmarks'!$C$10+G15*'Ad Benchmarks'!$D$10)+G16*'Ad Benchmarks'!$B$17),0) -> 2925.9423 | H38: =IFERROR(H31/((H13*'Ad Benchmarks'!$B$10+H14*'Ad Benchmarks'!$C$10+H15*'Ad Benchmarks'!$D$10)+H16*'Ad Benchmarks'!$B$17),0) -> 2307.8006 | I38: =IFERROR(I31/((I13*'Ad Benchmarks'!$B$10+I14*'Ad Benchmarks'!$C$10+I15*'Ad Benchmarks'!$D$10)+I16*'Ad Benchmarks'!$B$17),0) -> 2370.1046 | ... N38: =IFERROR(N31/((N13*'Ad Benchmarks'!$B$10+N14*'Ad Benchmarks'!$C$10+N15*'Ad Benchmarks'!$D$10)+N16*'Ad Benchmarks'!$B$17),0) -> 2521.9744
A39: ROAS, first paid month | B39: =IFERROR((B13*'Ad Benchmarks'!$B$10+B14*'Ad Benchmarks'!$C$10+B15*'Ad Benchmarks'!$D$10)*Inputs!$B$22/B6,0) -> 0.53888507 | C39: =IFERROR((C13*'Ad Benchmarks'!$B$10+C14*'Ad Benchmarks'!$C$10+C15*'Ad Benchmarks'!$D$10)*Inputs!$B$22/C6,0) -> 0.53888507 | D39: =IFERROR((D13*'Ad Benchmarks'!$B$10+D14*'Ad Benchmarks'!$C$10+D15*'Ad Benchmarks'!$D$10)*Inputs!$B$22/D6,0) -> 0.53888507 | E39: =IFERROR((E13*'Ad Benchmarks'!$B$10+E14*'Ad Benchmarks'!$C$10+E15*'Ad Benchmarks'!$D$10)*Inputs!$B$22/E6,0) -> 0.53888507 | F39: =IFERROR((F13*'Ad Benchmarks'!$B$10+F14*'Ad Benchmarks'!$C$10+F15*'Ad Benchmarks'!$D$10)*Inputs!$B$22/F6,0) -> 0.53888507 | G39: =IFERROR((G13*'Ad Benchmarks'!$B$10+G14*'Ad Benchmarks'!$C$10+G15*'Ad Benchmarks'!$D$10)*Inputs!$B$22/G6,0) -> 0.53888507 | H39: =IFERROR((H13*'Ad Benchmarks'!$B$10+H14*'Ad Benchmarks'!$C$10+H15*'Ad Benchmarks'!$D$10)*Inputs!$B$22/H6,0) -> 0.53888507 | I39: =IFERROR((I13*'Ad Benchmarks'!$B$10+I14*'Ad Benchmarks'!$C$10+I15*'Ad Benchmarks'!$D$10)*Inputs!$B$22/I6,0) -> 0.53888507 | ... N39: =IFERROR((N13*'Ad Benchmarks'!$B$10+N14*'Ad Benchmarks'!$C$10+N15*'Ad Benchmarks'!$D$10)*Inputs!$B$22/N6,0) -> 0.53888507
A40: ROAS, 12-month value of stores won | B40: =IFERROR((B13*'Ad Benchmarks'!$B$10+B14*'Ad Benchmarks'!$C$10+B15*'Ad Benchmarks'!$D$10)*'Ad Benchmarks'!$B$20/B6,0) -> 5.2176233 | C40: =IFERROR((C13*'Ad Benchmarks'!$B$10+C14*'Ad Benchmarks'!$C$10+C15*'Ad Benchmarks'!$D$10)*'Ad Benchmarks'!$B$20/C6,0) -> 5.2176233 | D40: =IFERROR((D13*'Ad Benchmarks'!$B$10+D14*'Ad Benchmarks'!$C$10+D15*'Ad Benchmarks'!$D$10)*'Ad Benchmarks'!$B$20/D6,0) -> 5.2176233 | E40: =IFERROR((E13*'Ad Benchmarks'!$B$10+E14*'Ad Benchmarks'!$C$10+E15*'Ad Benchmarks'!$D$10)*'Ad Benchmarks'!$B$20/E6,0) -> 5.2176233 | F40: =IFERROR((F13*'Ad Benchmarks'!$B$10+F14*'Ad Benchmarks'!$C$10+F15*'Ad Benchmarks'!$D$10)*'Ad Benchmarks'!$B$20/F6,0) -> 5.2176233 | G40: =IFERROR((G13*'Ad Benchmarks'!$B$10+G14*'Ad Benchmarks'!$C$10+G15*'Ad Benchmarks'!$D$10)*'Ad Benchmarks'!$B$20/G6,0) -> 5.2176233 | H40: =IFERROR((H13*'Ad Benchmarks'!$B$10+H14*'Ad Benchmarks'!$C$10+H15*'Ad Benchmarks'!$D$10)*'Ad Benchmarks'!$B$20/H6,0) -> 5.2176233 | I40: =IFERROR((I13*'Ad Benchmarks'!$B$10+I14*'Ad Benchmarks'!$C$10+I15*'Ad Benchmarks'!$D$10)*'Ad Benchmarks'!$B$20/I6,0) -> 5.2176233 | ... N40: =IFERROR((N13*'Ad Benchmarks'!$B$10+N14*'Ad Benchmarks'!$C$10+N15*'Ad Benchmarks'!$D$10)*'Ad Benchmarks'!$B$20/N6,0) -> 5.2176233
A41: LTV : CAC (all-in) | B41: =IFERROR('Ad Benchmarks'!$B$21/B38,0) -> 8.3874024 | C41: =IFERROR('Ad Benchmarks'!$B$21/C38,0) -> 9.7330444 | D41: =IFERROR('Ad Benchmarks'!$B$21/D38,0) -> 10.380501 | E41: =IFERROR('Ad Benchmarks'!$B$21/E38,0) -> 8.7121772 | F41: =IFERROR('Ad Benchmarks'!$B$21/F38,0) -> 11.232942 | G41: =IFERROR('Ad Benchmarks'!$B$21/G38,0) -> 9.3629195 | H41: =IFERROR('Ad Benchmarks'!$B$21/H38,0) -> 11.870767 | I41: =IFERROR('Ad Benchmarks'!$B$21/I38,0) -> 11.558714 | ... N41: =IFERROR('Ad Benchmarks'!$B$21/N38,0) -> 10.862665
...
